mai 14 00:02:25 raspberrypi mainApp.py[2526]: [DataToLocalInfluxDB] : write_points 100
mai 14 00:02:38 raspberrypi mainApp.py[2526]: [DataToLocalInfluxDB] : data not saved, timeout ! HTTPConnectionPool(host='localhost', port=8086): Max retries exceeded with url: /write?db=SensorData (Caused by NewConnectionError('<urllib3.connection.HTTPConnection object at 0x74bc8350>: Failed to establish a new connection: [Errno 111] Connection refused'))
mai 14 00:02:38 raspberrypi mainApp.py[2526]: [DataToLocalInfluxDB] : data not saved, timeout ! HTTPConnectionPool(host='localhost', port=8086): Max retries exceeded with url: /write?db=SensorData (Caused by NewConnectionError('<urllib3.connection.HTTPConnection object at 0x74bc88f0>: Failed to establish a new connection: [Errno 111] Connection refused'))
mai 14 00:02:38 raspberrypi mainApp.py[2526]: [DataToLocalInfluxDB] : data not saved, timeout ! HTTPConnectionPool(host='localhost', port=8086): Max retries exceeded with url: /write?db=SensorData (Caused by NewConnectionError('<urllib3.connection.HTTPConnection object at 0x74be50b0>: Failed to establish a new connection: [Errno 111] Connection refused'))
mai 14 00:02:38 raspberrypi mainApp.py[2526]: [DataToLocalInfluxDB] : data not saved, timeout ! HTTPConnectionPool(host='localhost', port=8086): Max retries exceeded with url: /write?db=SensorData (Caused by NewConnectionError('<urllib3.connection.HTTPConnection object at 0x74bc8d10>: Failed to establish a new connection: [Errno 111] Connection refused'))
mai 14 00:02:38 raspberrypi mainApp.py[2526]: [DataToLocalInfluxDB] : data not saved, timeout ! HTTPConnectionPool(host='localhost', port=8086): Max retries exceeded with url: /write?db=SensorData (Caused by NewConnectionError('<urllib3.connection.HTTPConnection object at 0x74bc84f0>: Failed to establish a new connection: [Errno 111] Connection refused'))
mai 14 00:02:38 raspberrypi mainApp.py[2526]: [DataToLocalInfluxDB] : data not saved, timeout ! HTTPConnectionPool(host='localhost', port=8086): Max retries exceeded with url: /write?db=SensorData (Caused by NewConnectionError('<urllib3.connection.HTTPConnection object at 0x74bc83b0>: Failed to establish a new connection: [Errno 111] Connection refused'))
mai 14 00:02:38 raspberrypi mainApp.py[2526]: [DataToLocalInfluxDB] : data not saved, timeout ! HTTPConnectionPool(host='localhost', port=8086): Max retries exceeded with url: /write?db=SensorData (Caused by NewConnectionError('<urllib3.connection.HTTPConnection object at 0x74be5510>: Failed to establish a new connection: [Errno 111] Connection refused'))
mai 14 00:02:38 raspberrypi mainApp.py[2526]: [DataToLocalInfluxDB] : data not saved, timeout ! HTTPConnectionPool(host='localhost', port=8086): Max retries exceeded with url: /write?db=SensorData (Caused by NewConnectionError('<urllib3.connection.HTTPConnection object at 0x74be5b10>: Failed to establish a new connection: [Errno 111] Connection refused'))
mai 14 00:02:38 raspberrypi mainApp.py[2526]: [DataToLocalInfluxDB] : data not saved, timeout ! HTTPConnectionPool(host='localhost', port=8086): Max retries exceeded with url: /write?db=SensorData (Caused by NewConnectionError('<urllib3.connection.HTTPConnection object at 0x74bc81f0>: Failed to establish a new connection: [Errno 111] Connection refused'))
mai 14 00:02:38 raspberrypi mainApp.py[2526]: [DataToLocalInfluxDB] : data not saved, timeout ! HTTPConnectionPool(host='localhost', port=8086): Max retries exceeded with url: /write?db=SensorData (Caused by NewConnectionError('<urllib3.connection.HTTPConnection object at 0x74bc88b0>: Failed to establish a new connection: [Errno 111] Connection refused'))
mai 14 00:02:38 raspberrypi mainApp.py[2526]: [DataToLocalInfluxDB] : data not saved, timeout ! HTTPConnectionPool(host='localhost', port=8086): Max retries exceeded with url: /write?db=SensorData (Caused by NewConnectionError('<urllib3.connection.HTTPConnection object at 0x74be5ab0>: Failed to establish a new connection: [Errno 111] Connection refused'))
mai 14 00:02:38 raspberrypi mainApp.py[2526]: [DataToLocalInfluxDB] : data not saved, timeout ! HTTPConnectionPool(host='localhost', port=8086): Max retries exceeded with url: /write?db=SensorData (Caused by NewConnectionError('<urllib3.connection.HTTPConnection object at 0x74be5690>: Failed to establish a new connection: [Errno 111] Connection refused'))
mai 14 00:02:38 raspberrypi mainApp.py[2526]: [DataToLocalInfluxDB] : data not saved, timeout ! HTTPConnectionPool(host='localhost', port=8086): Max retries exceeded with url: /write?db=SensorData (Caused by NewConnectionError('<urllib3.connection.HTTPConnection object at 0x74be53f0>: Failed to establish a new connection: [Errno 111] Connection refused'))
mai 14 00:02:38 raspberrypi mainApp.py[2526]: [DataToLocalInfluxDB] : data not saved, timeout ! HTTPConnectionPool(host='localhost', port=8086): Max retries exceeded with url: /write?db=SensorData (Caused by NewConnectionError('<urllib3.connection.HTTPConnection object at 0x74bc8f50>: Failed to establish a new connection: [Errno 111] Connection refused'))
mai 14 00:02:38 raspberrypi mainApp.py[2526]: [DataToLocalInfluxDB] : data not saved, timeout ! HTTPConnectionPool(host='localhost', port=8086): Max retries exceeded with url: /write?db=SensorData (Caused by NewConnectionError('<urllib3.connection.HTTPConnection object at 0x74bc8730>: Failed to establish a new connection: [Errno 111] Connection refused'))
mai 14 00:02:38 raspberrypi mainApp.py[2526]: [DataToLocalInfluxDB] : data not saved, timeout ! HTTPConnectionPool(host='localhost', port=8086): Max retries exceeded with url: /write?db=SensorData (Caused by NewConnectionError('<urllib3.connection.HTTPConnection object at 0x74be5ef0>: Failed to establish a new connection: [Errno 111] Connection refused'))
mai 14 00:02:39 raspberrypi mainApp.py[2526]: [DataToLocalInfluxDB] : data not saved, timeout ! HTTPConnectionPool(host='localhost', port=8086): Max retries exceeded with url: /write?db=SensorData (Caused by NewConnectionError('<urllib3.connection.HTTPConnection object at 0x74be5290>: Failed to establish a new connection: [Errno 111] Connection refused'))
mai 14 00:02:39 raspberrypi mainApp.py[2526]: [DataToLocalInfluxDB] : data not saved, timeout ! HTTPConnectionPool(host='localhost', port=8086): Max retries exceeded with url: /write?db=SensorData (Caused by NewConnectionError('<urllib3.connection.HTTPConnection object at 0x74be5770>: Failed to establish a new connection: [Errno 111] Connection refused'))
mai 14 00:02:39 raspberrypi mainApp.py[2526]: [DataToLocalInfluxDB] : data not saved, timeout ! HTTPConnectionPool(host='localhost', port=8086): Max retries exceeded with url: /write?db=SensorData (Caused by NewConnectionError('<urllib3.connection.HTTPConnection object at 0x74be5e10>: Failed to establish a new connection: [Errno 111] Connection refused'))
mai 14 00:02:39 raspberrypi mainApp.py[2526]: [DataToLocalInfluxDB] : data not saved, timeout ! HTTPConnectionPool(host='localhost', port=8086): Max retries exceeded with url: /write?db=SensorData (Caused by NewConnectionError('<urllib3.connection.HTTPConnection object at 0x74be5bf0>: Failed to establish a new connection: [Errno 111] Connection refused'))
mai 14 00:02:39 raspberrypi mainApp.py[2526]: [DataToLocalInfluxDB] : data not saved, timeout ! HTTPConnectionPool(host='localhost', port=8086): Max retries exceeded with url: /write?db=SensorData (Caused by NewConnectionError('<urllib3.connection.HTTPConnection object at 0x74be5d70>: Failed to establish a new connection: [Errno 111] Connection refused'))
mai 14 00:02:39 raspberrypi mainApp.py[2526]: [DataToLocalInfluxDB] : data not saved, timeout ! HTTPConnectionPool(host='localhost', port=8086): Max retries exceeded with url: /write?db=SensorData (Caused by NewConnectionError('<urllib3.connection.HTTPConnection object at 0x74bc82d0>: Failed to establish a new connection: [Errno 111] Connection refused'))
mai 14 00:02:39 raspberrypi mainApp.py[2526]: [DataToLocalInfluxDB] : data not saved, timeout ! HTTPConnectionPool(host='localhost', port=8086): Max retries exceeded with url: /write?db=SensorData (Caused by NewConnectionError('<urllib3.connection.HTTPConnection object at 0x74bc8b90>: Failed to establish a new connection: [Errno 111] Connection refused'))
mai 14 00:02:39 raspberrypi mainApp.py[2526]: [DataToLocalInfluxDB] : data not saved, timeout ! HTTPConnectionPool(host='localhost', port=8086): Max retries exceeded with url: /write?db=SensorData (Caused by NewConnectionError('<urllib3.connection.HTTPConnection object at 0x74bc8ef0>: Failed to establish a new connection: [Errno 111] Connection refused'))
mai 14 00:02:39 raspberrypi mainApp.py[2526]: [DataToLocalInfluxDB] : data not saved, timeout ! HTTPConnectionPool(host='localhost', port=8086): Max retries exceeded with url: /write?db=SensorData (Caused by NewConnectionError('<urllib3.connection.HTTPConnection object at 0x74bc8b50>: Failed to establish a new connection: [Errno 111] Connection refused'))
mai 14 00:02:39 raspberrypi mainApp.py[2526]: [DataToLocalInfluxDB] : data not saved, timeout ! HTTPConnectionPool(host='localhost', port=8086): Max retries exceeded with url: /write?db=SensorData (Caused by NewConnectionError('<urllib3.connection.HTTPConnection object at 0x74bc89b0>: Failed to establish a new connection: [Errno 111] Connection refused'))
mai 14 00:02:39 raspberrypi mainApp.py[2526]: [DataToLocalInfluxDB] : data not saved, timeout ! HTTPConnectionPool(host='localhost', port=8086): Max retries exceeded with url: /write?db=SensorData (Caused by NewConnectionError('<urllib3.connection.HTTPConnection object at 0x74be57d0>: Failed to establish a new connection: [Errno 111] Connection refused'))
mai 14 00:02:39 raspberrypi mainApp.py[2526]: [DataToLocalInfluxDB] : data not saved, timeout ! HTTPConnectionPool(host='localhost', port=8086): Max retries exceeded with url: /write?db=SensorData (Caused by NewConnectionError('<urllib3.connection.HTTPConnection object at 0x74be5450>: Failed to establish a new connection: [Errno 111] Connection refused'))
mai 14 00:02:39 raspberrypi mainApp.py[2526]: [DataToLocalInfluxDB] : data not saved, timeout ! HTTPConnectionPool(host='localhost', port=8086): Max retries exceeded with url: /write?db=SensorData (Caused by NewConnectionError('<urllib3.connection.HTTPConnection object at 0x74be5b90>: Failed to establish a new connection: [Errno 111] Connection refused'))
mai 14 00:02:39 raspberrypi mainApp.py[2526]: [DataToLocalInfluxDB] : data not saved, timeout ! HTTPConnectionPool(host='localhost', port=8086): Max retries exceeded with url: /write?db=SensorData (Caused by NewConnectionError('<urllib3.connection.HTTPConnection object at 0x74be5150>: Failed to establish a new connection: [Errno 111] Connection refused'))
mai 14 00:02:40 raspberrypi mainApp.py[2526]: [DataToLocalInfluxDB] : data not saved, timeout ! HTTPConnectionPool(host='localhost', port=8086): Max retries exceeded with url: /write?db=SensorData (Caused by NewConnectionError('<urllib3.connection.HTTPConnection object at 0x74be5650>: Failed to establish a new connection: [Errno 111] Connection refused'))
mai 14 00:02:40 raspberrypi mainApp.py[2526]: [DataToLocalInfluxDB] : data not saved, timeout ! HTTPConnectionPool(host='localhost', port=8086): Max retries exceeded with url: /write?db=SensorData (Caused by NewConnectionError('<urllib3.connection.HTTPConnection object at 0x74be5170>: Failed to establish a new connection: [Errno 111] Connection refused'))
mai 14 00:02:40 raspberrypi mainApp.py[2526]: [DataToLocalInfluxDB] : data not saved, timeout ! HTTPConnectionPool(host='localhost', port=8086): Max retries exceeded with url: /write?db=SensorData (Caused by NewConnectionError('<urllib3.connection.HTTPConnection object at 0x74bc83d0>: Failed to establish a new connection: [Errno 111] Connection refused'))
mai 14 00:02:40 raspberrypi mainApp.py[2526]: [DataToLocalInfluxDB] : data not saved, timeout ! HTTPConnectionPool(host='localhost', port=8086): Max retries exceeded with url: /write?db=SensorData (Caused by NewConnectionError('<urllib3.connection.HTTPConnection object at 0x74bc8990>: Failed to establish a new connection: [Errno 111] Connection refused'))
mai 14 00:02:40 raspberrypi mainApp.py[2526]: [DataToLocalInfluxDB] : data not saved, timeout ! HTTPConnectionPool(host='localhost', port=8086): Max retries exceeded with url: /write?db=SensorData (Caused by NewConnectionError('<urllib3.connection.HTTPConnection object at 0x74b77430>: Failed to establish a new connection: [Errno 111] Connection refused'))
mai 14 00:02:40 raspberrypi mainApp.py[2526]: [DataToLocalInfluxDB] : data not saved, timeout ! HTTPConnectionPool(host='localhost', port=8086): Max retries exceeded with url: /write?db=SensorData (Caused by NewConnectionError('<urllib3.connection.HTTPConnection object at 0x74bc8d50>: Failed to establish a new connection: [Errno 111] Connection refused'))
mai 14 00:02:40 raspberrypi mainApp.py[2526]: [DataToLocalInfluxDB] : data not saved, timeout ! HTTPConnectionPool(host='localhost', port=8086): Max retries exceeded with url: /write?db=SensorData (Caused by NewConnectionError('<urllib3.connection.HTTPConnection object at 0x74bc8570>: Failed to establish a new connection: [Errno 111] Connection refused'))
mai 14 00:02:40 raspberrypi mainApp.py[2526]: [DataToLocalInfluxDB] : data not saved, timeout ! HTTPConnectionPool(host='localhost', port=8086): Max retries exceeded with url: /write?db=SensorData (Caused by NewConnectionError('<urllib3.connection.HTTPConnection object at 0x74be55f0>: Failed to establish a new connection: [Errno 111] Connection refused'))
mai 14 00:02:40 raspberrypi mainApp.py[2526]: [DataToLocalInfluxDB] : data not saved, timeout ! HTTPConnectionPool(host='localhost', port=8086): Max retries exceeded with url: /write?db=SensorData (Caused by NewConnectionError('<urllib3.connection.HTTPConnection object at 0x74be54f0>: Failed to establish a new connection: [Errno 111] Connection refused'))
mai 14 00:02:40 raspberrypi mainApp.py[2526]: [DataToLocalInfluxDB] : data not saved, timeout ! HTTPConnectionPool(host='localhost', port=8086): Max retries exceeded with url: /write?db=SensorData (Caused by NewConnectionError('<urllib3.connection.HTTPConnection object at 0x74be5eb0>: Failed to establish a new connection: [Errno 111] Connection refused'))
mai 14 00:02:40 raspberrypi mainApp.py[2526]: [DataToLocalInfluxDB] : data not saved, timeout ! HTTPConnectionPool(host='localhost', port=8086): Max retries exceeded with url: /write?db=SensorData (Caused by NewConnectionError('<urllib3.connection.HTTPConnection object at 0x74bc8290>: Failed to establish a new connection: [Errno 111] Connection refused'))
mai 14 00:02:40 raspberrypi mainApp.py[2526]: [DataToLocalInfluxDB] : data not saved, timeout ! HTTPConnectionPool(host='localhost', port=8086): Max retries exceeded with url: /write?db=SensorData (Caused by NewConnectionError('<urllib3.connection.HTTPConnection object at 0x74bc8670>: Failed to establish a new connection: [Errno 111] Connection refused'))
mai 14 00:02:41 raspberrypi mainApp.py[2526]: [DataToLocalInfluxDB] : data not saved, timeout ! HTTPConnectionPool(host='localhost', port=8086): Max retries exceeded with url: /write?db=SensorData (Caused by NewConnectionError('<urllib3.connection.HTTPConnection object at 0x74bc8970>: Failed to establish a new connection: [Errno 111] Connection refused'))
mai 14 00:02:41 raspberrypi mainApp.py[2526]: [DataToLocalInfluxDB] : data not saved, timeout ! HTTPConnectionPool(host='localhost', port=8086): Max retries exceeded with url: /write?db=SensorData (Caused by NewConnectionError('<urllib3.connection.HTTPConnection object at 0x74be5970>: Failed to establish a new connection: [Errno 111] Connection refused'))
mai 14 00:02:41 raspberrypi mainApp.py[2526]: [DataToLocalInfluxDB] : data not saved, timeout ! HTTPConnectionPool(host='localhost', port=8086): Max retries exceeded with url: /write?db=SensorData (Caused by NewConnectionError('<urllib3.connection.HTTPConnection object at 0x74be57b0>: Failed to establish a new connection: [Errno 111] Connection refused'))
mai 14 00:02:41 raspberrypi mainApp.py[2526]: [DataToLocalInfluxDB] : data not saved, timeout ! HTTPConnectionPool(host='localhost', port=8086): Max retries exceeded with url: /write?db=SensorData (Caused by NewConnectionError('<urllib3.connection.HTTPConnection object at 0x74be51b0>: Failed to establish a new connection: [Errno 111] Connection refused'))
mai 14 00:02:41 raspberrypi mainApp.py[2526]: [DataToLocalInfluxDB] : data not saved, timeout ! HTTPConnectionPool(host='localhost', port=8086): Max retries exceeded with url: /write?db=SensorData (Caused by NewConnectionError('<urllib3.connection.HTTPConnection object at 0x74be5c90>: Failed to establish a new connection: [Errno 111] Connection refused'))
mai 14 00:02:41 raspberrypi mainApp.py[2526]: [DataToLocalInfluxDB] : data not saved, timeout ! HTTPConnectionPool(host='localhost', port=8086): Max retries exceeded with url: /write?db=SensorData (Caused by NewConnectionError('<urllib3.connection.HTTPConnection object at 0x74be5690>: Failed to establish a new connection: [Errno 111] Connection refused'))
mai 14 00:02:41 raspberrypi mainApp.py[2526]: [DataToLocalInfluxDB] : data not saved, timeout ! HTTPConnectionPool(host='localhost', port=8086): Max retries exceeded with url: /write?db=SensorData (Caused by NewConnectionError('<urllib3.connection.HTTPConnection object at 0x74be5570>: Failed to establish a new connection: [Errno 111] Connection refused'))
mai 14 00:02:41 raspberrypi mainApp.py[2526]: [DataToLocalInfluxDB] : data not saved, timeout ! HTTPConnectionPool(host='localhost', port=8086): Max retries exceeded with url: /write?db=SensorData (Caused by NewConnectionError('<urllib3.connection.HTTPConnection object at 0x74bc8fd0>: Failed to establish a new connection: [Errno 111] Connection refused'))
mai 14 00:02:41 raspberrypi mainApp.py[2526]: [DataToLocalInfluxDB] : data not saved, timeout ! HTTPConnectionPool(host='localhost', port=8086): Max retries exceeded with url: /write?db=SensorData (Caused by NewConnectionError('<urllib3.connection.HTTPConnection object at 0x74bc8670>: Failed to establish a new connection: [Errno 111] Connection refused'))
mai 14 00:02:41 raspberrypi mainApp.py[2526]: [DataToLocalInfluxDB] : data not saved, timeout ! HTTPConnectionPool(host='localhost', port=8086): Max retries exceeded with url: /write?db=SensorData (Caused by NewConnectionError('<urllib3.connection.HTTPConnection object at 0x74b77190>: Failed to establish a new connection: [Errno 111] Connection refused'))
mai 14 00:02:41 raspberrypi mainApp.py[2526]: [DataToLocalInfluxDB] : data not saved, timeout ! HTTPConnectionPool(host='localhost', port=8086): Max retries exceeded with url: /write?db=SensorData (Caused by NewConnectionError('<urllib3.connection.HTTPConnection object at 0x74bc8590>: Failed to establish a new connection: [Errno 111] Connection refused'))
mai 14 00:02:41 raspberrypi mainApp.py[2526]: [DataToLocalInfluxDB] : data not saved, timeout ! HTTPConnectionPool(host='localhost', port=8086): Max retries exceeded with url: /write?db=SensorData (Caused by NewConnectionError('<urllib3.connection.HTTPConnection object at 0x74bc8990>: Failed to establish a new connection: [Errno 111] Connection refused'))
mai 14 00:02:41 raspberrypi mainApp.py[2526]: [DataToLocalInfluxDB] : data not saved, timeout ! HTTPConnectionPool(host='localhost', port=8086): Max retries exceeded with url: /write?db=SensorData (Caused by NewConnectionError('<urllib3.connection.HTTPConnection object at 0x74be56d0>: Failed to establish a new connection: [Errno 111] Connection refused'))
mai 14 00:02:41 raspberrypi mainApp.py[2526]: [DataToLocalInfluxDB] : data not saved, timeout ! HTTPConnectionPool(host='localhost', port=8086): Max retries exceeded with url: /write?db=SensorData (Caused by NewConnectionError('<urllib3.connection.HTTPConnection object at 0x74be5410>: Failed to establish a new connection: [Errno 111] Connection refused'))
mai 14 00:02:41 raspberrypi mainApp.py[2526]: [DataToLocalInfluxDB] : data not saved, timeout ! HTTPConnectionPool(host='localhost', port=8086): Max retries exceeded with url: /write?db=SensorData (Caused by NewConnectionError('<urllib3.connection.HTTPConnection object at 0x74be5450>: Failed to establish a new connection: [Errno 111] Connection refused'))
mai 14 00:02:41 raspberrypi mainApp.py[2526]: [DataToLocalInfluxDB] : data not saved, timeout ! HTTPConnectionPool(host='localhost', port=8086): Max retries exceeded with url: /write?db=SensorData (Caused by NewConnectionError('<urllib3.connection.HTTPConnection object at 0x74be5710>: Failed to establish a new connection: [Errno 111] Connection refused'))
mai 14 00:02:42 raspberrypi mainApp.py[2526]: [DataToLocalInfluxDB] : data not saved, timeout ! HTTPConnectionPool(host='localhost', port=8086): Max retries exceeded with url: /write?db=SensorData (Caused by NewConnectionError('<urllib3.connection.HTTPConnection object at 0x74be5310>: Failed to establish a new connection: [Errno 111] Connection refused'))
mai 14 00:02:42 raspberrypi mainApp.py[2526]: [DataToLocalInfluxDB] : data not saved, timeout ! HTTPConnectionPool(host='localhost', port=8086): Max retries exceeded with url: /write?db=SensorData (Caused by NewConnectionError('<urllib3.connection.HTTPConnection object at 0x74bc8df0>: Failed to establish a new connection: [Errno 111] Connection refused'))
mai 14 00:02:42 raspberrypi mainApp.py[2526]: [DataToLocalInfluxDB] : data not saved, timeout ! HTTPConnectionPool(host='localhost', port=8086): Max retries exceeded with url: /write?db=SensorData (Caused by NewConnectionError('<urllib3.connection.HTTPConnection object at 0x74bc8ff0>: Failed to establish a new connection: [Errno 111] Connection refused'))
mai 14 00:02:42 raspberrypi mainApp.py[2526]: [DataToLocalInfluxDB] : data not saved, timeout ! HTTPConnectionPool(host='localhost', port=8086): Max retries exceeded with url: /write?db=SensorData (Caused by NewConnectionError('<urllib3.connection.HTTPConnection object at 0x74bc85d0>: Failed to establish a new connection: [Errno 111] Connection refused'))
mai 14 00:02:42 raspberrypi mainApp.py[2526]: [DataToLocalInfluxDB] : data not saved, timeout ! HTTPConnectionPool(host='localhost', port=8086): Max retries exceeded with url: /write?db=SensorData (Caused by NewConnectionError('<urllib3.connection.HTTPConnection object at 0x74b772b0>: Failed to establish a new connection: [Errno 111] Connection refused'))
mai 14 00:02:42 raspberrypi mainApp.py[2526]: [DataToLocalInfluxDB] : data not saved, timeout ! HTTPConnectionPool(host='localhost', port=8086): Max retries exceeded with url: /write?db=SensorData (Caused by NewConnectionError('<urllib3.connection.HTTPConnection object at 0x74bc8a50>: Failed to establish a new connection: [Errno 111] Connection refused'))
mai 14 00:02:42 raspberrypi mainApp.py[2526]: [DataToLocalInfluxDB] : data not saved, timeout ! HTTPConnectionPool(host='localhost', port=8086): Max retries exceeded with url: /write?db=SensorData (Caused by NewConnectionError('<urllib3.connection.HTTPConnection object at 0x74bc83d0>: Failed to establish a new connection: [Errno 111] Connection refused'))
mai 14 00:02:42 raspberrypi mainApp.py[2526]: [DataToLocalInfluxDB] : data not saved, timeout ! HTTPConnectionPool(host='localhost', port=8086): Max retries exceeded with url: /write?db=SensorData (Caused by NewConnectionError('<urllib3.connection.HTTPConnection object at 0x74be56d0>: Failed to establish a new connection: [Errno 111] Connection refused'))
mai 14 00:02:42 raspberrypi mainApp.py[2526]: [DataToLocalInfluxDB] : data not saved, timeout ! HTTPConnectionPool(host='localhost', port=8086): Max retries exceeded with url: /write?db=SensorData (Caused by NewConnectionError('<urllib3.connection.HTTPConnection object at 0x74be5810>: Failed to establish a new connection: [Errno 111] Connection refused'))
mai 14 00:02:42 raspberrypi mainApp.py[2526]: [DataToLocalInfluxDB] : data not saved, timeout ! HTTPConnectionPool(host='localhost', port=8086): Max retries exceeded with url: /write?db=SensorData (Caused by NewConnectionError('<urllib3.connection.HTTPConnection object at 0x74be50d0>: Failed to establish a new connection: [Errno 111] Connection refused'))
mai 14 00:02:42 raspberrypi mainApp.py[2526]: [DataToLocalInfluxDB] : data not saved, timeout ! HTTPConnectionPool(host='localhost', port=8086): Max retries exceeded with url: /write?db=SensorData (Caused by NewConnectionError('<urllib3.connection.HTTPConnection object at 0x74be50f0>: Failed to establish a new connection: [Errno 111] Connection refused'))
mai 14 00:02:42 raspberrypi mainApp.py[2526]: [DataToLocalInfluxDB] : data not saved, timeout ! HTTPConnectionPool(host='localhost', port=8086): Max retries exceeded with url: /write?db=SensorData (Caused by NewConnectionError('<urllib3.connection.HTTPConnection object at 0x74be5870>: Failed to establish a new connection: [Errno 111] Connection refused'))
mai 14 00:02:42 raspberrypi mainApp.py[2526]: [DataToLocalInfluxDB] : data not saved, timeout ! HTTPConnectionPool(host='localhost', port=8086): Max retries exceeded with url: /write?db=SensorData (Caused by NewConnectionError('<urllib3.connection.HTTPConnection object at 0x74be5a30>: Failed to establish a new connection: [Errno 111] Connection refused'))
mai 14 00:02:42 raspberrypi mainApp.py[2526]: [DataToLocalInfluxDB] : data not saved, timeout ! HTTPConnectionPool(host='localhost', port=8086): Max retries exceeded with url: /write?db=SensorData (Caused by NewConnectionError('<urllib3.connection.HTTPConnection object at 0x74bc8230>: Failed to establish a new connection: [Errno 111] Connection refused'))
mai 14 00:02:42 raspberrypi mainApp.py[2526]: [DataToLocalInfluxDB] : data not saved, timeout ! HTTPConnectionPool(host='localhost', port=8086): Max retries exceeded with url: /write?db=SensorData (Caused by NewConnectionError('<urllib3.connection.HTTPConnection object at 0x74bc8490>: Failed to establish a new connection: [Errno 111] Connection refused'))
mai 14 00:02:42 raspberrypi mainApp.py[2526]: [DataToLocalInfluxDB] : data not saved, timeout ! HTTPConnectionPool(host='localhost', port=8086): Max retries exceeded with url: /write?db=SensorData (Caused by NewConnectionError('<urllib3.connection.HTTPConnection object at 0x74b770b0>: Failed to establish a new connection: [Errno 111] Connection refused'))
mai 14 00:02:43 raspberrypi mainApp.py[2526]: [DataToLocalInfluxDB] : data not saved, timeout ! HTTPConnectionPool(host='localhost', port=8086): Max retries exceeded with url: /write?db=SensorData (Caused by NewConnectionError('<urllib3.connection.HTTPConnection object at 0x74bc8f90>: Failed to establish a new connection: [Errno 111] Connection refused'))
mai 14 00:02:43 raspberrypi mainApp.py[2526]: [DataToLocalInfluxDB] : data not saved, timeout ! HTTPConnectionPool(host='localhost', port=8086): Max retries exceeded with url: /write?db=SensorData (Caused by NewConnectionError('<urllib3.connection.HTTPConnection object at 0x74bc8b10>: Failed to establish a new connection: [Errno 111] Connection refused'))
mai 14 00:02:43 raspberrypi mainApp.py[2526]: [DataToLocalInfluxDB] : data not saved, timeout ! HTTPConnectionPool(host='localhost', port=8086): Max retries exceeded with url: /write?db=SensorData (Caused by NewConnectionError('<urllib3.connection.HTTPConnection object at 0x74be58d0>: Failed to establish a new connection: [Errno 111] Connection refused'))
mai 14 00:02:43 raspberrypi mainApp.py[2526]: [DataToLocalInfluxDB] : data not saved, timeout ! HTTPConnectionPool(host='localhost', port=8086): Max retries exceeded with url: /write?db=SensorData (Caused by NewConnectionError('<urllib3.connection.HTTPConnection object at 0x74be5390>: Failed to establish a new connection: [Errno 111] Connection refused'))
mai 14 00:02:43 raspberrypi mainApp.py[2526]: [DataToLocalInfluxDB] : data not saved, timeout ! HTTPConnectionPool(host='localhost', port=8086): Max retries exceeded with url: /write?db=SensorData (Caused by NewConnectionError('<urllib3.connection.HTTPConnection object at 0x74be5510>: Failed to establish a new connection: [Errno 111] Connection refused'))
mai 14 00:02:43 raspberrypi mainApp.py[2526]: [DataToLocalInfluxDB] : data not saved, timeout ! HTTPConnectionPool(host='localhost', port=8086): Max retries exceeded with url: /write?db=SensorData (Caused by NewConnectionError('<urllib3.connection.HTTPConnection object at 0x74be50b0>: Failed to establish a new connection: [Errno 111] Connection refused'))
mai 14 00:02:43 raspberrypi mainApp.py[2526]: [DataToLocalInfluxDB] : data not saved, timeout ! HTTPConnectionPool(host='localhost', port=8086): Max retries exceeded with url: /write?db=SensorData (Caused by NewConnectionError('<urllib3.connection.HTTPConnection object at 0x74be5370>: Failed to establish a new connection: [Errno 111] Connection refused'))
mai 14 00:02:43 raspberrypi mainApp.py[2526]: [DataToLocalInfluxDB] : data not saved, timeout ! HTTPConnectionPool(host='localhost', port=8086): Max retries exceeded with url: /write?db=SensorData (Caused by NewConnectionError('<urllib3.connection.HTTPConnection object at 0x74be5670>: Failed to establish a new connection: [Errno 111] Connection refused'))
mai 14 00:02:43 raspberrypi mainApp.py[2526]: [DataToLocalInfluxDB] : data not saved, timeout ! HTTPConnectionPool(host='localhost', port=8086): Max retries exceeded with url: /write?db=SensorData (Caused by NewConnectionError('<urllib3.connection.HTTPConnection object at 0x74bc8e10>: Failed to establish a new connection: [Errno 111] Connection refused'))
mai 14 00:02:43 raspberrypi mainApp.py[2526]: [DataToLocalInfluxDB] : data not saved, timeout ! HTTPConnectionPool(host='localhost', port=8086): Max retries exceeded with url: /write?db=SensorData (Caused by NewConnectionError('<urllib3.connection.HTTPConnection object at 0x74bc8470>: Failed to establish a new connection: [Errno 111] Connection refused'))
mai 14 00:02:43 raspberrypi mainApp.py[2526]: [DataToLocalInfluxDB] : data not saved, timeout ! HTTPConnectionPool(host='localhost', port=8086): Max retries exceeded with url: /write?db=SensorData (Caused by NewConnectionError('<urllib3.connection.HTTPConnection object at 0x74b77790>: Failed to establish a new connection: [Errno 111] Connection refused'))
mai 14 00:02:43 raspberrypi mainApp.py[2526]: [DataToLocalInfluxDB] : data not saved, timeout ! HTTPConnectionPool(host='localhost', port=8086): Max retries exceeded with url: /write?db=SensorData (Caused by NewConnectionError('<urllib3.connection.HTTPConnection object at 0x74bc8b70>: Failed to establish a new connection: [Errno 111] Connection refused'))
mai 14 00:02:43 raspberrypi mainApp.py[2526]: [DataToLocalInfluxDB] : data not saved, timeout ! HTTPConnectionPool(host='localhost', port=8086): Max retries exceeded with url: /write?db=SensorData (Caused by NewConnectionError('<urllib3.connection.HTTPConnection object at 0x74bc8550>: Failed to establish a new connection: [Errno 111] Connection refused'))
mai 14 00:02:43 raspberrypi mainApp.py[2526]: [DataToLocalInfluxDB] : data not saved, timeout ! HTTPConnectionPool(host='localhost', port=8086): Max retries exceeded with url: /write?db=SensorData (Caused by NewConnectionError('<urllib3.connection.HTTPConnection object at 0x74be5590>: Failed to establish a new connection: [Errno 111] Connection refused'))
mai 14 00:02:43 raspberrypi mainApp.py[2526]: [DataToLocalInfluxDB] : data not saved, timeout ! HTTPConnectionPool(host='localhost', port=8086): Max retries exceeded with url: /write?db=SensorData (Caused by NewConnectionError('<urllib3.connection.HTTPConnection object at 0x74be5cb0>: Failed to establish a new connection: [Errno 111] Connection refused'))
mai 14 00:02:43 raspberrypi mainApp.py[2526]: [DataToLocalInfluxDB] : data not saved, timeout ! HTTPConnectionPool(host='localhost', port=8086): Max retries exceeded with url: /write?db=SensorData (Caused by NewConnectionError('<urllib3.connection.HTTPConnection object at 0x74be56d0>: Failed to establish a new connection: [Errno 111] Connection refused'))
mai 14 00:02:43 raspberrypi mainApp.py[2526]: [DataToLocalInfluxDB] : data not saved, timeout ! HTTPConnectionPool(host='localhost', port=8086): Max retries exceeded with url: /write?db=SensorData (Caused by NewConnectionError('<urllib3.connection.HTTPConnection object at 0x74be52d0>: Failed to establish a new connection: [Errno 111] Connection refused'))
mai 14 00:02:43 raspberrypi mainApp.py[2526]: [DataToLocalInfluxDB] : data not saved, timeout ! HTTPConnectionPool(host='localhost', port=8086): Max retries exceeded with url: /write?db=SensorData (Caused by NewConnectionError('<urllib3.connection.HTTPConnection object at 0x74be5e10>: Failed to establish a new connection: [Errno 111] Connection refused'))
mai 14 00:02:44 raspberrypi mainApp.py[2526]: [DataToLocalInfluxDB] : data not saved, timeout ! HTTPConnectionPool(host='localhost', port=8086): Max retries exceeded with url: /write?db=SensorData (Caused by NewConnectionError('<urllib3.connection.HTTPConnection object at 0x74be5cf0>: Failed to establish a new connection: [Errno 111] Connection refused'))
mai 14 00:02:44 raspberrypi mainApp.py[2526]: [DataToLocalInfluxDB] : data not saved, timeout ! HTTPConnectionPool(host='localhost', port=8086): Max retries exceeded with url: /write?db=SensorData (Caused by NewConnectionError('<urllib3.connection.HTTPConnection object at 0x74bc8750>: Failed to establish a new connection: [Errno 111] Connection refused'))
mai 14 00:02:44 raspberrypi mainApp.py[2526]: [DataToLocalInfluxDB] : data not saved, timeout ! HTTPConnectionPool(host='localhost', port=8086): Max retries exceeded with url: /write?db=SensorData (Caused by NewConnectionError('<urllib3.connection.HTTPConnection object at 0x74bc8c50>: Failed to establish a new connection: [Errno 111] Connection refused'))
mai 14 00:02:44 raspberrypi mainApp.py[2526]: [DataToLocalInfluxDB] : data not saved, timeout ! HTTPConnectionPool(host='localhost', port=8086): Max retries exceeded with url: /write?db=SensorData (Caused by NewConnectionError('<urllib3.connection.HTTPConnection object at 0x74b77730>: Failed to establish a new connection: [Errno 111] Connection refused'))
mai 14 00:02:44 raspberrypi mainApp.py[2526]: [DataToLocalInfluxDB] : data not saved, timeout ! HTTPConnectionPool(host='localhost', port=8086): Max retries exceeded with url: /write?db=SensorData (Caused by NewConnectionError('<urllib3.connection.HTTPConnection object at 0x74bc88b0>: Failed to establish a new connection: [Errno 111] Connection refused'))
mai 14 00:02:44 raspberrypi mainApp.py[2526]: [DataToLocalInfluxDB] : data not saved, timeout ! HTTPConnectionPool(host='localhost', port=8086): Max retries exceeded with url: /write?db=SensorData (Caused by NewConnectionError('<urllib3.connection.HTTPConnection object at 0x74bc8ad0>: Failed to establish a new connection: [Errno 111] Connection refused'))
mai 14 00:02:44 raspberrypi mainApp.py[2526]: [DataToLocalInfluxDB] : data not saved, timeout ! HTTPConnectionPool(host='localhost', port=8086): Max retries exceeded with url: /write?db=SensorData (Caused by NewConnectionError('<urllib3.connection.HTTPConnection object at 0x74be5bb0>: Failed to establish a new connection: [Errno 111] Connection refused'))
mai 14 00:02:44 raspberrypi mainApp.py[2526]: [DataToLocalInfluxDB] : data not saved, timeout ! HTTPConnectionPool(host='localhost', port=8086): Max retries exceeded with url: /write?db=SensorData (Caused by NewConnectionError('<urllib3.connection.HTTPConnection object at 0x74be5750>: Failed to establish a new connection: [Errno 111] Connection refused'))
mai 14 00:02:44 raspberrypi mainApp.py[2526]: [DataToLocalInfluxDB] : data not saved, timeout ! HTTPConnectionPool(host='localhost', port=8086): Max retries exceeded with url: /write?db=SensorData (Caused by NewConnectionError('<urllib3.connection.HTTPConnection object at 0x74be59b0>: Failed to establish a new connection: [Errno 111] Connection refused'))
mai 14 00:02:44 raspberrypi mainApp.py[2526]: [DataToLocalInfluxDB] : data not saved, timeout ! HTTPConnectionPool(host='localhost', port=8086): Max retries exceeded with url: /write?db=SensorData (Caused by NewConnectionError('<urllib3.connection.HTTPConnection object at 0x74be5a90>: Failed to establish a new connection: [Errno 111] Connection refused'))
mai 14 00:02:44 raspberrypi mainApp.py[2526]: [DataToLocalInfluxDB] : data not saved, timeout ! HTTPConnectionPool(host='localhost', port=8086): Max retries exceeded with url: /write?db=SensorData (Caused by NewConnectionError('<urllib3.connection.HTTPConnection object at 0x74be5150>: Failed to establish a new connection: [Errno 111] Connection refused'))
mai 14 00:02:44 raspberrypi mainApp.py[2526]: [DataToLocalInfluxDB] : data not saved, timeout ! HTTPConnectionPool(host='localhost', port=8086): Max retries exceeded with url: /write?db=SensorData (Caused by NewConnectionError('<urllib3.connection.HTTPConnection object at 0x74be5970>: Failed to establish a new connection: [Errno 111] Connection refused'))
mai 14 00:02:44 raspberrypi mainApp.py[2526]: [DataToLocalInfluxDB] : data not saved, timeout ! HTTPConnectionPool(host='localhost', port=8086): Max retries exceeded with url: /write?db=SensorData (Caused by NewConnectionError('<urllib3.connection.HTTPConnection object at 0x74bc8e90>: Failed to establish a new connection: [Errno 111] Connection refused'))
mai 14 00:02:44 raspberrypi mainApp.py[2526]: [DataToLocalInfluxDB] : data not saved, timeout ! HTTPConnectionPool(host='localhost', port=8086): Max retries exceeded with url: /write?db=SensorData (Caused by NewConnectionError('<urllib3.connection.HTTPConnection object at 0x74bc8bf0>: Failed to establish a new connection: [Errno 111] Connection refused'))
mai 14 00:02:44 raspberrypi mainApp.py[2526]: [DataToLocalInfluxDB] : data not saved, timeout ! HTTPConnectionPool(host='localhost', port=8086): Max retries exceeded with url: /write?db=SensorData (Caused by NewConnectionError('<urllib3.connection.HTTPConnection object at 0x74b771b0>: Failed to establish a new connection: [Errno 111] Connection refused'))
mai 14 00:02:44 raspberrypi mainApp.py[2526]: [DataToLocalInfluxDB] : data not saved, timeout ! HTTPConnectionPool(host='localhost', port=8086): Max retries exceeded with url: /write?db=SensorData (Caused by NewConnectionError('<urllib3.connection.HTTPConnection object at 0x74bc8150>: Failed to establish a new connection: [Errno 111] Connection refused'))
mai 14 00:02:45 raspberrypi mainApp.py[2526]: [DataToLocalInfluxDB] : data not saved, timeout ! HTTPConnectionPool(host='localhost', port=8086): Max retries exceeded with url: /write?db=SensorData (Caused by NewConnectionError('<urllib3.connection.HTTPConnection object at 0x74bc8f70>: Failed to establish a new connection: [Errno 111] Connection refused'))
mai 14 00:02:45 raspberrypi mainApp.py[2526]: [DataToLocalInfluxDB] : data not saved, timeout ! HTTPConnectionPool(host='localhost', port=8086): Max retries exceeded with url: /write?db=SensorData (Caused by NewConnectionError('<urllib3.connection.HTTPConnection object at 0x74be5130>: Failed to establish a new connection: [Errno 111] Connection refused'))
mai 14 00:02:45 raspberrypi mainApp.py[2526]: [DataToLocalInfluxDB] : data not saved, timeout ! HTTPConnectionPool(host='localhost', port=8086): Max retries exceeded with url: /write?db=SensorData (Caused by NewConnectionError('<urllib3.connection.HTTPConnection object at 0x74be5830>: Failed to establish a new connection: [Errno 111] Connection refused'))
mai 14 00:02:45 raspberrypi mainApp.py[2526]: [DataToLocalInfluxDB] : data not saved, timeout ! HTTPConnectionPool(host='localhost', port=8086): Max retries exceeded with url: /write?db=SensorData (Caused by NewConnectionError('<urllib3.connection.HTTPConnection object at 0x74be5510>: Failed to establish a new connection: [Errno 111] Connection refused'))
mai 14 00:02:45 raspberrypi mainApp.py[2526]: [DataToLocalInfluxDB] : data not saved, timeout ! HTTPConnectionPool(host='localhost', port=8086): Max retries exceeded with url: /write?db=SensorData (Caused by NewConnectionError('<urllib3.connection.HTTPConnection object at 0x74be5230>: Failed to establish a new connection: [Errno 111] Connection refused'))
mai 14 00:02:45 raspberrypi mainApp.py[2526]: [DataToLocalInfluxDB] : data not saved, timeout ! HTTPConnectionPool(host='localhost', port=8086): Max retries exceeded with url: /write?db=SensorData (Caused by NewConnectionError('<urllib3.connection.HTTPConnection object at 0x74be5330>: Failed to establish a new connection: [Errno 111] Connection refused'))
mai 14 00:02:45 raspberrypi mainApp.py[2526]: [DataToLocalInfluxDB] : data not saved, timeout ! HTTPConnectionPool(host='localhost', port=8086): Max retries exceeded with url: /write?db=SensorData (Caused by NewConnectionError('<urllib3.connection.HTTPConnection object at 0x74be5730>: Failed to establish a new connection: [Errno 111] Connection refused'))
mai 14 00:02:45 raspberrypi mainApp.py[2526]: [DataToLocalInfluxDB] : data not saved, timeout ! HTTPConnectionPool(host='localhost', port=8086): Max retries exceeded with url: /write?db=SensorData (Caused by NewConnectionError('<urllib3.connection.HTTPConnection object at 0x74bc8370>: Failed to establish a new connection: [Errno 111] Connection refused'))
mai 14 00:02:45 raspberrypi mainApp.py[2526]: [DataToLocalInfluxDB] : data not saved, timeout ! HTTPConnectionPool(host='localhost', port=8086): Max retries exceeded with url: /write?db=SensorData (Caused by NewConnectionError('<urllib3.connection.HTTPConnection object at 0x74bc8550>: Failed to establish a new connection: [Errno 111] Connection refused'))
mai 14 00:02:45 raspberrypi mainApp.py[2526]: [DataToLocalInfluxDB] : data not saved, timeout ! HTTPConnectionPool(host='localhost', port=8086): Max retries exceeded with url: /write?db=SensorData (Caused by NewConnectionError('<urllib3.connection.HTTPConnection object at 0x74bc8730>: Failed to establish a new connection: [Errno 111] Connection refused'))
mai 14 00:02:45 raspberrypi mainApp.py[2526]: [DataToLocalInfluxDB] : data not saved, timeout ! HTTPConnectionPool(host='localhost', port=8086): Max retries exceeded with url: /write?db=SensorData (Caused by NewConnectionError('<urllib3.connection.HTTPConnection object at 0x74bc84b0>: Failed to establish a new connection: [Errno 111] Connection refused'))
mai 14 00:02:45 raspberrypi mainApp.py[2526]: [DataToLocalInfluxDB] : data not saved, timeout ! HTTPConnectionPool(host='localhost', port=8086): Max retries exceeded with url: /write?db=SensorData (Caused by NewConnectionError('<urllib3.connection.HTTPConnection object at 0x74bc8b30>: Failed to establish a new connection: [Errno 111] Connection refused'))
mai 14 00:02:45 raspberrypi mainApp.py[2526]: [DataToLocalInfluxDB] : data not saved, timeout ! HTTPConnectionPool(host='localhost', port=8086): Max retries exceeded with url: /write?db=SensorData (Caused by NewConnectionError('<urllib3.connection.HTTPConnection object at 0x74be5130>: Failed to establish a new connection: [Errno 111] Connection refused'))
mai 14 00:02:45 raspberrypi mainApp.py[2526]: [DataToLocalInfluxDB] : data not saved, timeout ! HTTPConnectionPool(host='localhost', port=8086): Max retries exceeded with url: /write?db=SensorData (Caused by NewConnectionError('<urllib3.connection.HTTPConnection object at 0x74be5db0>: Failed to establish a new connection: [Errno 111] Connection refused'))
mai 14 00:02:45 raspberrypi mainApp.py[2526]: [DataToLocalInfluxDB] : data not saved, timeout ! HTTPConnectionPool(host='localhost', port=8086): Max retries exceeded with url: /write?db=SensorData (Caused by NewConnectionError('<urllib3.connection.HTTPConnection object at 0x74be5990>: Failed to establish a new connection: [Errno 111] Connection refused'))
mai 14 00:02:45 raspberrypi mainApp.py[2526]: [DataToLocalInfluxDB] : data not saved, timeout ! HTTPConnectionPool(host='localhost', port=8086): Max retries exceeded with url: /write?db=SensorData (Caused by NewConnectionError('<urllib3.connection.HTTPConnection object at 0x74be5410>: Failed to establish a new connection: [Errno 111] Connection refused'))
mai 14 00:02:46 raspberrypi mainApp.py[2526]: [DataToLocalInfluxDB] : data not saved, timeout ! HTTPConnectionPool(host='localhost', port=8086): Max retries exceeded with url: /write?db=SensorData (Caused by NewConnectionError('<urllib3.connection.HTTPConnection object at 0x74be52b0>: Failed to establish a new connection: [Errno 111] Connection refused'))
mai 14 00:02:46 raspberrypi mainApp.py[2526]: [DataToLocalInfluxDB] : data not saved, timeout ! HTTPConnectionPool(host='localhost', port=8086): Max retries exceeded with url: /write?db=SensorData (Caused by NewConnectionError('<urllib3.connection.HTTPConnection object at 0x74be5c70>: Failed to establish a new connection: [Errno 111] Connection refused'))
mai 14 00:02:46 raspberrypi mainApp.py[2526]: [DataToLocalInfluxDB] : data not saved, timeout ! HTTPConnectionPool(host='localhost', port=8086): Max retries exceeded with url: /write?db=SensorData (Caused by NewConnectionError('<urllib3.connection.HTTPConnection object at 0x74bc8990>: Failed to establish a new connection: [Errno 111] Connection refused'))
mai 14 00:02:46 raspberrypi mainApp.py[2526]: [DataToLocalInfluxDB] : data not saved, timeout ! HTTPConnectionPool(host='localhost', port=8086): Max retries exceeded with url: /write?db=SensorData (Caused by NewConnectionError('<urllib3.connection.HTTPConnection object at 0x74bc8150>: Failed to establish a new connection: [Errno 111] Connection refused'))
mai 14 00:02:46 raspberrypi mainApp.py[2526]: [DataToLocalInfluxDB] : data not saved, timeout ! HTTPConnectionPool(host='localhost', port=8086): Max retries exceeded with url: /write?db=SensorData (Caused by NewConnectionError('<urllib3.connection.HTTPConnection object at 0x74bc82f0>: Failed to establish a new connection: [Errno 111] Connection refused'))
mai 14 00:02:46 raspberrypi mainApp.py[2526]: [DataToLocalInfluxDB] : data not saved, timeout ! HTTPConnectionPool(host='localhost', port=8086): Max retries exceeded with url: /write?db=SensorData (Caused by NewConnectionError('<urllib3.connection.HTTPConnection object at 0x74bc8930>: Failed to establish a new connection: [Errno 111] Connection refused'))
mai 14 00:02:46 raspberrypi mainApp.py[2526]: [DataToLocalInfluxDB] : data not saved, timeout ! HTTPConnectionPool(host='localhost', port=8086): Max retries exceeded with url: /write?db=SensorData (Caused by NewConnectionError('<urllib3.connection.HTTPConnection object at 0x74bc8230>: Failed to establish a new connection: [Errno 111] Connection refused'))
mai 14 00:02:46 raspberrypi mainApp.py[2526]: [DataToLocalInfluxDB] : data not saved, timeout ! HTTPConnectionPool(host='localhost', port=8086): Max retries exceeded with url: /write?db=SensorData (Caused by NewConnectionError('<urllib3.connection.HTTPConnection object at 0x74bc86f0>: Failed to establish a new connection: [Errno 111] Connection refused'))
mai 14 00:02:46 raspberrypi mainApp.py[2526]: [DataToLocalInfluxDB] : data not saved, timeout ! HTTPConnectionPool(host='localhost', port=8086): Max retries exceeded with url: /write?db=SensorData (Caused by NewConnectionError('<urllib3.connection.HTTPConnection object at 0x74be5e30>: Failed to establish a new connection: [Errno 111] Connection refused'))
mai 14 00:02:46 raspberrypi mainApp.py[2526]: [DataToLocalInfluxDB] : data not saved, timeout ! HTTPConnectionPool(host='localhost', port=8086): Max retries exceeded with url: /write?db=SensorData (Caused by NewConnectionError('<urllib3.connection.HTTPConnection object at 0x74be5170>: Failed to establish a new connection: [Errno 111] Connection refused'))
mai 14 00:02:46 raspberrypi mainApp.py[2526]: [DataToLocalInfluxDB] : data not saved, timeout ! HTTPConnectionPool(host='localhost', port=8086): Max retries exceeded with url: /write?db=SensorData (Caused by NewConnectionError('<urllib3.connection.HTTPConnection object at 0x74b77290>: Failed to establish a new connection: [Errno 111] Connection refused'))
mai 14 00:02:46 raspberrypi mainApp.py[2526]: [DataToLocalInfluxDB] : data not saved, timeout ! HTTPConnectionPool(host='localhost', port=8086): Max retries exceeded with url: /write?db=SensorData (Caused by NewConnectionError('<urllib3.connection.HTTPConnection object at 0x74be5db0>: Failed to establish a new connection: [Errno 111] Connection refused'))
mai 14 00:02:46 raspberrypi mainApp.py[2526]: [DataToLocalInfluxDB] : data not saved, timeout ! HTTPConnectionPool(host='localhost', port=8086): Max retries exceeded with url: /write?db=SensorData (Caused by NewConnectionError('<urllib3.connection.HTTPConnection object at 0x74be5ff0>: Failed to establish a new connection: [Errno 111] Connection refused'))
mai 14 00:02:47 raspberrypi mainApp.py[2526]: [DataToLocalInfluxDB] : data not saved, timeout ! HTTPConnectionPool(host='localhost', port=8086): Max retries exceeded with url: /write?db=SensorData (Caused by NewConnectionError('<urllib3.connection.HTTPConnection object at 0x74bc86f0>: Failed to establish a new connection: [Errno 111] Connection refused'))
mai 14 00:02:47 raspberrypi mainApp.py[2526]: [DataToLocalInfluxDB] : data not saved, timeout ! HTTPConnectionPool(host='localhost', port=8086): Max retries exceeded with url: /write?db=SensorData (Caused by NewConnectionError('<urllib3.connection.HTTPConnection object at 0x74bc89d0>: Failed to establish a new connection: [Errno 111] Connection refused'))
mai 14 00:02:47 raspberrypi mainApp.py[2526]: [DataToLocalInfluxDB] : data not saved, timeout ! HTTPConnectionPool(host='localhost', port=8086): Max retries exceeded with url: /write?db=SensorData (Caused by NewConnectionError('<urllib3.connection.HTTPConnection object at 0x74bc8e70>: Failed to establish a new connection: [Errno 111] Connection refused'))
mai 14 00:02:47 raspberrypi mainApp.py[2526]: [DataToLocalInfluxDB] : data not saved, timeout ! HTTPConnectionPool(host='localhost', port=8086): Max retries exceeded with url: /write?db=SensorData (Caused by NewConnectionError('<urllib3.connection.HTTPConnection object at 0x74bc8830>: Failed to establish a new connection: [Errno 111] Connection refused'))
mai 14 00:02:47 raspberrypi mainApp.py[2526]: [DataToLocalInfluxDB] : data not saved, timeout ! HTTPConnectionPool(host='localhost', port=8086): Max retries exceeded with url: /write?db=SensorData (Caused by NewConnectionError('<urllib3.connection.HTTPConnection object at 0x74bc81f0>: Failed to establish a new connection: [Errno 111] Connection refused'))
mai 14 00:02:47 raspberrypi mainApp.py[2526]: [DataToLocalInfluxDB] : data not saved, timeout ! HTTPConnectionPool(host='localhost', port=8086): Max retries exceeded with url: /write?db=SensorData (Caused by NewConnectionError('<urllib3.connection.HTTPConnection object at 0x74be5b90>: Failed to establish a new connection: [Errno 111] Connection refused'))
mai 14 00:02:47 raspberrypi mainApp.py[2526]: [DataToLocalInfluxDB] : data not saved, timeout ! HTTPConnectionPool(host='localhost', port=8086): Max retries exceeded with url: /write?db=SensorData (Caused by NewConnectionError('<urllib3.connection.HTTPConnection object at 0x74be5690>: Failed to establish a new connection: [Errno 111] Connection refused'))
mai 14 00:02:47 raspberrypi mainApp.py[2526]: [DataToLocalInfluxDB] : data not saved, timeout ! HTTPConnectionPool(host='localhost', port=8086): Max retries exceeded with url: /write?db=SensorData (Caused by NewConnectionError('<urllib3.connection.HTTPConnection object at 0x74be5dd0>: Failed to establish a new connection: [Errno 111] Connection refused'))
mai 14 00:02:47 raspberrypi mainApp.py[2526]: [DataToLocalInfluxDB] : data not saved, timeout ! HTTPConnectionPool(host='localhost', port=8086): Max retries exceeded with url: /write?db=SensorData (Caused by NewConnectionError('<urllib3.connection.HTTPConnection object at 0x74b773f0>: Failed to establish a new connection: [Errno 111] Connection refused'))
mai 14 00:02:47 raspberrypi mainApp.py[2526]: [DataToLocalInfluxDB] : data not saved, timeout ! HTTPConnectionPool(host='localhost', port=8086): Max retries exceeded with url: /write?db=SensorData (Caused by NewConnectionError('<urllib3.connection.HTTPConnection object at 0x74be5ed0>: Failed to establish a new connection: [Errno 111] Connection refused'))
mai 14 00:02:47 raspberrypi mainApp.py[2526]: [DataToLocalInfluxDB] : data not saved, timeout ! HTTPConnectionPool(host='localhost', port=8086): Max retries exceeded with url: /write?db=SensorData (Caused by NewConnectionError('<urllib3.connection.HTTPConnection object at 0x74be5e30>: Failed to establish a new connection: [Errno 111] Connection refused'))
mai 14 00:02:47 raspberrypi mainApp.py[2526]: [DataToLocalInfluxDB] : data not saved, timeout ! HTTPConnectionPool(host='localhost', port=8086): Max retries exceeded with url: /write?db=SensorData (Caused by NewConnectionError('<urllib3.connection.HTTPConnection object at 0x74bc8f30>: Failed to establish a new connection: [Errno 111] Connection refused'))
mai 14 00:02:47 raspberrypi mainApp.py[2526]: [DataToLocalInfluxDB] : data not saved, timeout ! HTTPConnectionPool(host='localhost', port=8086): Max retries exceeded with url: /write?db=SensorData (Caused by NewConnectionError('<urllib3.connection.HTTPConnection object at 0x74bc8ab0>: Failed to establish a new connection: [Errno 111] Connection refused'))
mai 14 00:02:47 raspberrypi mainApp.py[2526]: [DataToLocalInfluxDB] : data not saved, timeout ! HTTPConnectionPool(host='localhost', port=8086): Max retries exceeded with url: /write?db=SensorData (Caused by NewConnectionError('<urllib3.connection.HTTPConnection object at 0x74bc8790>: Failed to establish a new connection: [Errno 111] Connection refused'))
mai 14 00:02:47 raspberrypi mainApp.py[2526]: [DataToLocalInfluxDB] : data not saved, timeout ! HTTPConnectionPool(host='localhost', port=8086): Max retries exceeded with url: /write?db=SensorData (Caused by NewConnectionError('<urllib3.connection.HTTPConnection object at 0x74bc8610>: Failed to establish a new connection: [Errno 111] Connection refused'))
mai 14 00:02:48 raspberrypi mainApp.py[2526]: [DataToLocalInfluxDB] : data not saved, timeout ! HTTPConnectionPool(host='localhost', port=8086): Max retries exceeded with url: /write?db=SensorData (Caused by NewConnectionError('<urllib3.connection.HTTPConnection object at 0x74bc8490>: Failed to establish a new connection: [Errno 111] Connection refused'))
mai 14 00:02:48 raspberrypi mainApp.py[2526]: [DataToLocalInfluxDB] : data not saved, timeout ! HTTPConnectionPool(host='localhost', port=8086): Max retries exceeded with url: /write?db=SensorData (Caused by NewConnectionError('<urllib3.connection.HTTPConnection object at 0x74bc8c90>: Failed to establish a new connection: [Errno 111] Connection refused'))
mai 14 00:02:48 raspberrypi mainApp.py[2526]: [DataToLocalInfluxDB] : data not saved, timeout ! HTTPConnectionPool(host='localhost', port=8086): Max retries exceeded with url: /write?db=SensorData (Caused by NewConnectionError('<urllib3.connection.HTTPConnection object at 0x74be5770>: Failed to establish a new connection: [Errno 111] Connection refused'))
mai 14 00:02:48 raspberrypi mainApp.py[2526]: [DataToLocalInfluxDB] : data not saved, timeout ! HTTPConnectionPool(host='localhost', port=8086): Max retries exceeded with url: /write?db=SensorData (Caused by NewConnectionError('<urllib3.connection.HTTPConnection object at 0x74be5750>: Failed to establish a new connection: [Errno 111] Connection refused'))
mai 14 00:02:48 raspberrypi mainApp.py[2526]: [DataToLocalInfluxDB] : data not saved, timeout ! HTTPConnectionPool(host='localhost', port=8086): Max retries exceeded with url: /write?db=SensorData (Caused by NewConnectionError('<urllib3.connection.HTTPConnection object at 0x74b77750>: Failed to establish a new connection: [Errno 111] Connection refused'))
mai 14 00:02:48 raspberrypi mainApp.py[2526]: [DataToLocalInfluxDB] : data not saved, timeout ! HTTPConnectionPool(host='localhost', port=8086): Max retries exceeded with url: /write?db=SensorData (Caused by NewConnectionError('<urllib3.connection.HTTPConnection object at 0x74be5a10>: Failed to establish a new connection: [Errno 111] Connection refused'))
mai 14 00:02:48 raspberrypi mainApp.py[2526]: [DataToLocalInfluxDB] : data not saved, timeout ! HTTPConnectionPool(host='localhost', port=8086): Max retries exceeded with url: /write?db=SensorData (Caused by NewConnectionError('<urllib3.connection.HTTPConnection object at 0x74be5390>: Failed to establish a new connection: [Errno 111] Connection refused'))
mai 14 00:02:48 raspberrypi mainApp.py[2526]: [DataToLocalInfluxDB] : data not saved, timeout ! HTTPConnectionPool(host='localhost', port=8086): Max retries exceeded with url: /write?db=SensorData (Caused by NewConnectionError('<urllib3.connection.HTTPConnection object at 0x74bc8ad0>: Failed to establish a new connection: [Errno 111] Connection refused'))
mai 14 00:02:48 raspberrypi mainApp.py[2526]: [DataToLocalInfluxDB] : data not saved, timeout ! HTTPConnectionPool(host='localhost', port=8086): Max retries exceeded with url: /write?db=SensorData (Caused by NewConnectionError('<urllib3.connection.HTTPConnection object at 0x74bc81b0>: Failed to establish a new connection: [Errno 111] Connection refused'))
mai 14 00:02:48 raspberrypi mainApp.py[2526]: [DataToLocalInfluxDB] : data not saved, timeout ! HTTPConnectionPool(host='localhost', port=8086): Max retries exceeded with url: /write?db=SensorData (Caused by NewConnectionError('<urllib3.connection.HTTPConnection object at 0x74bc8bb0>: Failed to establish a new connection: [Errno 111] Connection refused'))
mai 14 00:02:48 raspberrypi mainApp.py[2526]: [DataToLocalInfluxDB] : data not saved, timeout ! HTTPConnectionPool(host='localhost', port=8086): Max retries exceeded with url: /write?db=SensorData (Caused by NewConnectionError('<urllib3.connection.HTTPConnection object at 0x74bc8eb0>: Failed to establish a new connection: [Errno 111] Connection refused'))
mai 14 00:02:48 raspberrypi mainApp.py[2526]: [DataToLocalInfluxDB] : data not saved, timeout ! HTTPConnectionPool(host='localhost', port=8086): Max retries exceeded with url: /write?db=SensorData (Caused by NewConnectionError('<urllib3.connection.HTTPConnection object at 0x74bc8230>: Failed to establish a new connection: [Errno 111] Connection refused'))
mai 14 00:02:48 raspberrypi mainApp.py[2526]: [DataToLocalInfluxDB] : data not saved, timeout ! HTTPConnectionPool(host='localhost', port=8086): Max retries exceeded with url: /write?db=SensorData (Caused by NewConnectionError('<urllib3.connection.HTTPConnection object at 0x74bc8830>: Failed to establish a new connection: [Errno 111] Connection refused'))
mai 14 00:02:49 raspberrypi mainApp.py[2526]: [DataToLocalInfluxDB] : data not saved, timeout ! HTTPConnectionPool(host='localhost', port=8086): Max retries exceeded with url: /write?db=SensorData (Caused by NewConnectionError('<urllib3.connection.HTTPConnection object at 0x74be52b0>: Failed to establish a new connection: [Errno 111] Connection refused'))
mai 14 00:02:49 raspberrypi mainApp.py[2526]: [DataToLocalInfluxDB] : data not saved, timeout ! HTTPConnectionPool(host='localhost', port=8086): Max retries exceeded with url: /write?db=SensorData (Caused by NewConnectionError('<urllib3.connection.HTTPConnection object at 0x74be53f0>: Failed to establish a new connection: [Errno 111] Connection refused'))
mai 14 00:02:49 raspberrypi mainApp.py[2526]: [DataToLocalInfluxDB] : data not saved, timeout ! HTTPConnectionPool(host='localhost', port=8086): Max retries exceeded with url: /write?db=SensorData (Caused by NewConnectionError('<urllib3.connection.HTTPConnection object at 0x74b776b0>: Failed to establish a new connection: [Errno 111] Connection refused'))
mai 14 00:02:49 raspberrypi mainApp.py[2526]: [DataToLocalInfluxDB] : data not saved, timeout ! HTTPConnectionPool(host='localhost', port=8086): Max retries exceeded with url: /write?db=SensorData (Caused by NewConnectionError('<urllib3.connection.HTTPConnection object at 0x74be58f0>: Failed to establish a new connection: [Errno 111] Connection refused'))
mai 14 00:02:49 raspberrypi mainApp.py[2526]: [DataToLocalInfluxDB] : data not saved, timeout ! HTTPConnectionPool(host='localhost', port=8086): Max retries exceeded with url: /write?db=SensorData (Caused by NewConnectionError('<urllib3.connection.HTTPConnection object at 0x74be5510>: Failed to establish a new connection: [Errno 111] Connection refused'))
mai 14 00:02:49 raspberrypi mainApp.py[2526]: [DataToLocalInfluxDB] : data not saved, timeout ! HTTPConnectionPool(host='localhost', port=8086): Max retries exceeded with url: /write?db=SensorData (Caused by NewConnectionError('<urllib3.connection.HTTPConnection object at 0x74bc8670>: Failed to establish a new connection: [Errno 111] Connection refused'))
mai 14 00:02:49 raspberrypi mainApp.py[2526]: [DataToLocalInfluxDB] : data not saved, timeout ! HTTPConnectionPool(host='localhost', port=8086): Max retries exceeded with url: /write?db=SensorData (Caused by NewConnectionError('<urllib3.connection.HTTPConnection object at 0x74bc85b0>: Failed to establish a new connection: [Errno 111] Connection refused'))
mai 14 00:02:49 raspberrypi mainApp.py[2526]: [DataToLocalInfluxDB] : data not saved, timeout ! HTTPConnectionPool(host='localhost', port=8086): Max retries exceeded with url: /write?db=SensorData (Caused by NewConnectionError('<urllib3.connection.HTTPConnection object at 0x74bc86d0>: Failed to establish a new connection: [Errno 111] Connection refused'))
mai 14 00:02:49 raspberrypi mainApp.py[2526]: [DataToLocalInfluxDB] : data not saved, timeout ! HTTPConnectionPool(host='localhost', port=8086): Max retries exceeded with url: /write?db=SensorData (Caused by NewConnectionError('<urllib3.connection.HTTPConnection object at 0x74babf90>: Failed to establish a new connection: [Errno 111] Connection refused'))
mai 14 00:02:49 raspberrypi mainApp.py[2526]: [DataToLocalInfluxDB] : data not saved, timeout ! HTTPConnectionPool(host='localhost', port=8086): Max retries exceeded with url: /write?db=SensorData (Caused by NewConnectionError('<urllib3.connection.HTTPConnection object at 0x74bc84b0>: Failed to establish a new connection: [Errno 111] Connection refused'))
mai 14 00:02:49 raspberrypi mainApp.py[2526]: [DataToLocalInfluxDB] : data not saved, timeout ! HTTPConnectionPool(host='localhost', port=8086): Max retries exceeded with url: /write?db=SensorData (Caused by NewConnectionError('<urllib3.connection.HTTPConnection object at 0x74bc8410>: Failed to establish a new connection: [Errno 111] Connection refused'))
mai 14 00:02:49 raspberrypi mainApp.py[2526]: [DataToLocalInfluxDB] : data not saved, timeout ! HTTPConnectionPool(host='localhost', port=8086): Max retries exceeded with url: /write?db=SensorData (Caused by NewConnectionError('<urllib3.connection.HTTPConnection object at 0x74be5cb0>: Failed to establish a new connection: [Errno 111] Connection refused'))
mai 14 00:02:49 raspberrypi mainApp.py[2526]: [DataToLocalInfluxDB] : data not saved, timeout ! HTTPConnectionPool(host='localhost', port=8086): Max retries exceeded with url: /write?db=SensorData (Caused by NewConnectionError('<urllib3.connection.HTTPConnection object at 0x74be5b50>: Failed to establish a new connection: [Errno 111] Connection refused'))
mai 14 00:02:50 raspberrypi mainApp.py[2526]: [DataToLocalInfluxDB] : data not saved, timeout ! HTTPConnectionPool(host='localhost', port=8086): Max retries exceeded with url: /write?db=SensorData (Caused by NewConnectionError('<urllib3.connection.HTTPConnection object at 0x74be5d90>: Failed to establish a new connection: [Errno 111] Connection refused'))
mai 14 00:02:50 raspberrypi mainApp.py[2526]: [DataToLocalInfluxDB] : data not saved, timeout ! HTTPConnectionPool(host='localhost', port=8086): Max retries exceeded with url: /write?db=SensorData (Caused by NewConnectionError('<urllib3.connection.HTTPConnection object at 0x74be5fd0>: Failed to establish a new connection: [Errno 111] Connection refused'))
mai 14 00:02:50 raspberrypi mainApp.py[2526]: [DataToLocalInfluxDB] : data not saved, timeout ! HTTPConnectionPool(host='localhost', port=8086): Max retries exceeded with url: /write?db=SensorData (Caused by NewConnectionError('<urllib3.connection.HTTPConnection object at 0x74be5370>: Failed to establish a new connection: [Errno 111] Connection refused'))
mai 14 00:02:50 raspberrypi mainApp.py[2526]: [DataToLocalInfluxDB] : data not saved, timeout ! HTTPConnectionPool(host='localhost', port=8086): Max retries exceeded with url: /write?db=SensorData (Caused by NewConnectionError('<urllib3.connection.HTTPConnection object at 0x74be5970>: Failed to establish a new connection: [Errno 111] Connection refused'))
mai 14 00:02:50 raspberrypi mainApp.py[2526]: [DataToLocalInfluxDB] : data not saved, timeout ! HTTPConnectionPool(host='localhost', port=8086): Max retries exceeded with url: /write?db=SensorData (Caused by NewConnectionError('<urllib3.connection.HTTPConnection object at 0x74bc8bf0>: Failed to establish a new connection: [Errno 111] Connection refused'))
mai 14 00:02:50 raspberrypi mainApp.py[2526]: [DataToLocalInfluxDB] : data not saved, timeout ! HTTPConnectionPool(host='localhost', port=8086): Max retries exceeded with url: /write?db=SensorData (Caused by NewConnectionError('<urllib3.connection.HTTPConnection object at 0x74bc8550>: Failed to establish a new connection: [Errno 111] Connection refused'))
mai 14 00:02:50 raspberrypi mainApp.py[2526]: [DataToLocalInfluxDB] : data not saved, timeout ! HTTPConnectionPool(host='localhost', port=8086): Max retries exceeded with url: /write?db=SensorData (Caused by NewConnectionError('<urllib3.connection.HTTPConnection object at 0x74b77730>: Failed to establish a new connection: [Errno 111] Connection refused'))
mai 14 00:02:50 raspberrypi mainApp.py[2526]: [DataToLocalInfluxDB] : data not saved, timeout ! HTTPConnectionPool(host='localhost', port=8086): Max retries exceeded with url: /write?db=SensorData (Caused by NewConnectionError('<urllib3.connection.HTTPConnection object at 0x74bc8890>: Failed to establish a new connection: [Errno 111] Connection refused'))
mai 14 00:02:50 raspberrypi mainApp.py[2526]: [DataToLocalInfluxDB] : data not saved, timeout ! HTTPConnectionPool(host='localhost', port=8086): Max retries exceeded with url: /write?db=SensorData (Caused by NewConnectionError('<urllib3.connection.HTTPConnection object at 0x74bc81d0>: Failed to establish a new connection: [Errno 111] Connection refused'))
mai 14 00:02:50 raspberrypi mainApp.py[2526]: [DataToLocalInfluxDB] : data not saved, timeout ! HTTPConnectionPool(host='localhost', port=8086): Max retries exceeded with url: /write?db=SensorData (Caused by NewConnectionError('<urllib3.connection.HTTPConnection object at 0x74be5250>: Failed to establish a new connection: [Errno 111] Connection refused'))
mai 14 00:02:50 raspberrypi mainApp.py[2526]: [DataToLocalInfluxDB] : data not saved, timeout ! HTTPConnectionPool(host='localhost', port=8086): Max retries exceeded with url: /write?db=SensorData (Caused by NewConnectionError('<urllib3.connection.HTTPConnection object at 0x74be5690>: Failed to establish a new connection: [Errno 111] Connection refused'))
mai 14 00:02:50 raspberrypi mainApp.py[2526]: [DataToLocalInfluxDB] : data not saved, timeout ! HTTPConnectionPool(host='localhost', port=8086): Max retries exceeded with url: /write?db=SensorData (Caused by NewConnectionError('<urllib3.connection.HTTPConnection object at 0x74be5130>: Failed to establish a new connection: [Errno 111] Connection refused'))
mai 14 00:02:50 raspberrypi mainApp.py[2526]: [DataToLocalInfluxDB] : data not saved, timeout ! HTTPConnectionPool(host='localhost', port=8086): Max retries exceeded with url: /write?db=SensorData (Caused by NewConnectionError('<urllib3.connection.HTTPConnection object at 0x74be5130>: Failed to establish a new connection: [Errno 111] Connection refused'))
mai 14 00:02:51 raspberrypi mainApp.py[2526]: [DataToLocalInfluxDB] : data not saved, timeout ! HTTPConnectionPool(host='localhost', port=8086): Max retries exceeded with url: /write?db=SensorData (Caused by NewConnectionError('<urllib3.connection.HTTPConnection object at 0x74be5870>: Failed to establish a new connection: [Errno 111] Connection refused'))
mai 14 00:02:51 raspberrypi mainApp.py[2526]: [DataToLocalInfluxDB] : data not saved, timeout ! HTTPConnectionPool(host='localhost', port=8086): Max retries exceeded with url: /write?db=SensorData (Caused by NewConnectionError('<urllib3.connection.HTTPConnection object at 0x74be5470>: Failed to establish a new connection: [Errno 111] Connection refused'))
mai 14 00:02:51 raspberrypi mainApp.py[2526]: [DataToLocalInfluxDB] : data not saved, timeout ! HTTPConnectionPool(host='localhost', port=8086): Max retries exceeded with url: /write?db=SensorData (Caused by NewConnectionError('<urllib3.connection.HTTPConnection object at 0x74bc8fd0>: Failed to establish a new connection: [Errno 111] Connection refused'))
mai 14 00:02:51 raspberrypi mainApp.py[2526]: [DataToLocalInfluxDB] : data not saved, timeout ! HTTPConnectionPool(host='localhost', port=8086): Max retries exceeded with url: /write?db=SensorData (Caused by NewConnectionError('<urllib3.connection.HTTPConnection object at 0x74bc86f0>: Failed to establish a new connection: [Errno 111] Connection refused'))
mai 14 00:02:51 raspberrypi mainApp.py[2526]: [DataToLocalInfluxDB] : data not saved, timeout ! HTTPConnectionPool(host='localhost', port=8086): Max retries exceeded with url: /write?db=SensorData (Caused by NewConnectionError('<urllib3.connection.HTTPConnection object at 0x74b77c10>: Failed to establish a new connection: [Errno 111] Connection refused'))
mai 14 00:02:51 raspberrypi mainApp.py[2526]: [DataToLocalInfluxDB] : data not saved, timeout ! HTTPConnectionPool(host='localhost', port=8086): Max retries exceeded with url: /write?db=SensorData (Caused by NewConnectionError('<urllib3.connection.HTTPConnection object at 0x74bc8af0>: Failed to establish a new connection: [Errno 111] Connection refused'))
mai 14 00:02:51 raspberrypi mainApp.py[2526]: [DataToLocalInfluxDB] : data not saved, timeout ! HTTPConnectionPool(host='localhost', port=8086): Max retries exceeded with url: /write?db=SensorData (Caused by NewConnectionError('<urllib3.connection.HTTPConnection object at 0x74bc8750>: Failed to establish a new connection: [Errno 111] Connection refused'))
mai 14 00:02:51 raspberrypi mainApp.py[2526]: [DataToLocalInfluxDB] : data not saved, timeout ! HTTPConnectionPool(host='localhost', port=8086): Max retries exceeded with url: /write?db=SensorData (Caused by NewConnectionError('<urllib3.connection.HTTPConnection object at 0x74be5470>: Failed to establish a new connection: [Errno 111] Connection refused'))
mai 14 00:02:51 raspberrypi mainApp.py[2526]: [DataToLocalInfluxDB] : data not saved, timeout ! HTTPConnectionPool(host='localhost', port=8086): Max retries exceeded with url: /write?db=SensorData (Caused by NewConnectionError('<urllib3.connection.HTTPConnection object at 0x74be5690>: Failed to establish a new connection: [Errno 111] Connection refused'))
mai 14 00:02:51 raspberrypi mainApp.py[2526]: [DataToLocalInfluxDB] : data not saved, timeout ! HTTPConnectionPool(host='localhost', port=8086): Max retries exceeded with url: /write?db=SensorData (Caused by NewConnectionError('<urllib3.connection.HTTPConnection object at 0x74be5fb0>: Failed to establish a new connection: [Errno 111] Connection refused'))
mai 14 00:02:51 raspberrypi mainApp.py[2526]: [DataToLocalInfluxDB] : data not saved, timeout ! HTTPConnectionPool(host='localhost', port=8086): Max retries exceeded with url: /write?db=SensorData (Caused by NewConnectionError('<urllib3.connection.HTTPConnection object at 0x74be5dd0>: Failed to establish a new connection: [Errno 111] Connection refused'))
mai 14 00:02:51 raspberrypi mainApp.py[2526]: [DataToLocalInfluxDB] : data not saved, timeout ! HTTPConnectionPool(host='localhost', port=8086): Max retries exceeded with url: /write?db=SensorData (Caused by NewConnectionError('<urllib3.connection.HTTPConnection object at 0x74be57b0>: Failed to establish a new connection: [Errno 111] Connection refused'))
mai 14 00:02:51 raspberrypi mainApp.py[2526]: [DataToLocalInfluxDB] : data not saved, timeout ! HTTPConnectionPool(host='localhost', port=8086): Max retries exceeded with url: /write?db=SensorData (Caused by NewConnectionError('<urllib3.connection.HTTPConnection object at 0x74be5e90>: Failed to establish a new connection: [Errno 111] Connection refused'))
mai 14 00:02:52 raspberrypi mainApp.py[2526]: [DataToLocalInfluxDB] : data not saved, timeout ! HTTPConnectionPool(host='localhost', port=8086): Max retries exceeded with url: /write?db=SensorData (Caused by NewConnectionError('<urllib3.connection.HTTPConnection object at 0x74bc88f0>: Failed to establish a new connection: [Errno 111] Connection refused'))
mai 14 00:02:52 raspberrypi mainApp.py[2526]: [DataToLocalInfluxDB] : data not saved, timeout ! HTTPConnectionPool(host='localhost', port=8086): Max retries exceeded with url: /write?db=SensorData (Caused by NewConnectionError('<urllib3.connection.HTTPConnection object at 0x74bc84d0>: Failed to establish a new connection: [Errno 111] Connection refused'))
mai 14 00:02:52 raspberrypi mainApp.py[2526]: [DataToLocalInfluxDB] : data not saved, timeout ! HTTPConnectionPool(host='localhost', port=8086): Max retries exceeded with url: /write?db=SensorData (Caused by NewConnectionError('<urllib3.connection.HTTPConnection object at 0x74b77830>: Failed to establish a new connection: [Errno 111] Connection refused'))
mai 14 00:02:52 raspberrypi mainApp.py[2526]: [DataToLocalInfluxDB] : data not saved, timeout ! HTTPConnectionPool(host='localhost', port=8086): Max retries exceeded with url: /write?db=SensorData (Caused by NewConnectionError('<urllib3.connection.HTTPConnection object at 0x74bc8230>: Failed to establish a new connection: [Errno 111] Connection refused'))
mai 14 00:02:52 raspberrypi mainApp.py[2526]: [DataToLocalInfluxDB] : data not saved, timeout ! HTTPConnectionPool(host='localhost', port=8086): Max retries exceeded with url: /write?db=SensorData (Caused by NewConnectionError('<urllib3.connection.HTTPConnection object at 0x74bc81d0>: Failed to establish a new connection: [Errno 111] Connection refused'))
mai 14 00:02:52 raspberrypi mainApp.py[2526]: [DataToLocalInfluxDB] : data not saved, timeout ! HTTPConnectionPool(host='localhost', port=8086): Max retries exceeded with url: /write?db=SensorData (Caused by NewConnectionError('<urllib3.connection.HTTPConnection object at 0x74be5bb0>: Failed to establish a new connection: [Errno 111] Connection refused'))
mai 14 00:02:52 raspberrypi mainApp.py[2526]: [DataToLocalInfluxDB] : data not saved, timeout ! HTTPConnectionPool(host='localhost', port=8086): Max retries exceeded with url: /write?db=SensorData (Caused by NewConnectionError('<urllib3.connection.HTTPConnection object at 0x74be5050>: Failed to establish a new connection: [Errno 111] Connection refused'))
mai 14 00:02:52 raspberrypi mainApp.py[2526]: [DataToLocalInfluxDB] : data not saved, timeout ! HTTPConnectionPool(host='localhost', port=8086): Max retries exceeded with url: /write?db=SensorData (Caused by NewConnectionError('<urllib3.connection.HTTPConnection object at 0x74be5710>: Failed to establish a new connection: [Errno 111] Connection refused'))
mai 14 00:02:52 raspberrypi mainApp.py[2526]: [DataToLocalInfluxDB] : data not saved, timeout ! HTTPConnectionPool(host='localhost', port=8086): Max retries exceeded with url: /write?db=SensorData (Caused by NewConnectionError('<urllib3.connection.HTTPConnection object at 0x74be51b0>: Failed to establish a new connection: [Errno 111] Connection refused'))
mai 14 00:02:52 raspberrypi mainApp.py[2526]: [DataToLocalInfluxDB] : data not saved, timeout ! HTTPConnectionPool(host='localhost', port=8086): Max retries exceeded with url: /write?db=SensorData (Caused by NewConnectionError('<urllib3.connection.HTTPConnection object at 0x74be5b90>: Failed to establish a new connection: [Errno 111] Connection refused'))
mai 14 00:02:52 raspberrypi mainApp.py[2526]: [DataToLocalInfluxDB] : data not saved, timeout ! HTTPConnectionPool(host='localhost', port=8086): Max retries exceeded with url: /write?db=SensorData (Caused by NewConnectionError('<urllib3.connection.HTTPConnection object at 0x74be5c50>: Failed to establish a new connection: [Errno 111] Connection refused'))
mai 14 00:02:52 raspberrypi mainApp.py[2526]: [DataToLocalInfluxDB] : data not saved, timeout ! HTTPConnectionPool(host='localhost', port=8086): Max retries exceeded with url: /write?db=SensorData (Caused by NewConnectionError('<urllib3.connection.HTTPConnection object at 0x74bc8610>: Failed to establish a new connection: [Errno 111] Connection refused'))
mai 14 00:02:52 raspberrypi mainApp.py[2526]: [DataToLocalInfluxDB] : data not saved, timeout ! HTTPConnectionPool(host='localhost', port=8086): Max retries exceeded with url: /write?db=SensorData (Caused by NewConnectionError('<urllib3.connection.HTTPConnection object at 0x74bc8790>: Failed to establish a new connection: [Errno 111] Connection refused'))
mai 14 00:02:52 raspberrypi mainApp.py[2526]: [DataToLocalInfluxDB] : data not saved, timeout ! HTTPConnectionPool(host='localhost', port=8086): Max retries exceeded with url: /write?db=SensorData (Caused by NewConnectionError('<urllib3.connection.HTTPConnection object at 0x74b77990>: Failed to establish a new connection: [Errno 111] Connection refused'))
mai 14 00:02:53 raspberrypi mainApp.py[2526]: [DataToLocalInfluxDB] : data not saved, timeout ! HTTPConnectionPool(host='localhost', port=8086): Max retries exceeded with url: /write?db=SensorData (Caused by NewConnectionError('<urllib3.connection.HTTPConnection object at 0x74bc8af0>: Failed to establish a new connection: [Errno 111] Connection refused'))
mai 14 00:02:53 raspberrypi mainApp.py[2526]: [DataToLocalInfluxDB] : data not saved, timeout ! HTTPConnectionPool(host='localhost', port=8086): Max retries exceeded with url: /write?db=SensorData (Caused by NewConnectionError('<urllib3.connection.HTTPConnection object at 0x74bc8c70>: Failed to establish a new connection: [Errno 111] Connection refused'))
mai 14 00:02:53 raspberrypi mainApp.py[2526]: [DataToLocalInfluxDB] : data not saved, timeout ! HTTPConnectionPool(host='localhost', port=8086): Max retries exceeded with url: /write?db=SensorData (Caused by NewConnectionError('<urllib3.connection.HTTPConnection object at 0x74be56f0>: Failed to establish a new connection: [Errno 111] Connection refused'))
mai 14 00:02:53 raspberrypi mainApp.py[2526]: [DataToLocalInfluxDB] : data not saved, timeout ! HTTPConnectionPool(host='localhost', port=8086): Max retries exceeded with url: /write?db=SensorData (Caused by NewConnectionError('<urllib3.connection.HTTPConnection object at 0x74be5ff0>: Failed to establish a new connection: [Errno 111] Connection refused'))
mai 14 00:02:53 raspberrypi mainApp.py[2526]: [DataToLocalInfluxDB] : data not saved, timeout ! HTTPConnectionPool(host='localhost', port=8086): Max retries exceeded with url: /write?db=SensorData (Caused by NewConnectionError('<urllib3.connection.HTTPConnection object at 0x74be5df0>: Failed to establish a new connection: [Errno 111] Connection refused'))
mai 14 00:02:53 raspberrypi mainApp.py[2526]: [DataToLocalInfluxDB] : data not saved, timeout ! HTTPConnectionPool(host='localhost', port=8086): Max retries exceeded with url: /write?db=SensorData (Caused by NewConnectionError('<urllib3.connection.HTTPConnection object at 0x74be5b10>: Failed to establish a new connection: [Errno 111] Connection refused'))
mai 14 00:02:53 raspberrypi mainApp.py[2526]: [DataToLocalInfluxDB] : data not saved, timeout ! HTTPConnectionPool(host='localhost', port=8086): Max retries exceeded with url: /write?db=SensorData (Caused by NewConnectionError('<urllib3.connection.HTTPConnection object at 0x74be5790>: Failed to establish a new connection: [Errno 111] Connection refused'))
mai 14 00:02:53 raspberrypi mainApp.py[2526]: [DataToLocalInfluxDB] : data not saved, timeout ! HTTPConnectionPool(host='localhost', port=8086): Max retries exceeded with url: /write?db=SensorData (Caused by NewConnectionError('<urllib3.connection.HTTPConnection object at 0x74be54d0>: Failed to establish a new connection: [Errno 111] Connection refused'))
mai 14 00:02:53 raspberrypi mainApp.py[2526]: [DataToLocalInfluxDB] : data not saved, timeout ! HTTPConnectionPool(host='localhost', port=8086): Max retries exceeded with url: /write?db=SensorData (Caused by NewConnectionError('<urllib3.connection.HTTPConnection object at 0x74bc8e30>: Failed to establish a new connection: [Errno 111] Connection refused'))
mai 14 00:02:53 raspberrypi mainApp.py[2526]: [DataToLocalInfluxDB] : data not saved, timeout ! HTTPConnectionPool(host='localhost', port=8086): Max retries exceeded with url: /write?db=SensorData (Caused by NewConnectionError('<urllib3.connection.HTTPConnection object at 0x74bc88f0>: Failed to establish a new connection: [Errno 111] Connection refused'))
mai 14 00:02:53 raspberrypi mainApp.py[2526]: [DataToLocalInfluxDB] : data not saved, timeout ! HTTPConnectionPool(host='localhost', port=8086): Max retries exceeded with url: /write?db=SensorData (Caused by NewConnectionError('<urllib3.connection.HTTPConnection object at 0x74b77b70>: Failed to establish a new connection: [Errno 111] Connection refused'))
mai 14 00:02:53 raspberrypi mainApp.py[2526]: [DataToLocalInfluxDB] : data not saved, timeout ! HTTPConnectionPool(host='localhost', port=8086): Max retries exceeded with url: /write?db=SensorData (Caused by NewConnectionError('<urllib3.connection.HTTPConnection object at 0x74bc8f70>: Failed to establish a new connection: [Errno 111] Connection refused'))
mai 14 00:02:53 raspberrypi mainApp.py[2526]: [DataToLocalInfluxDB] : data not saved, timeout ! HTTPConnectionPool(host='localhost', port=8086): Max retries exceeded with url: /write?db=SensorData (Caused by NewConnectionError('<urllib3.connection.HTTPConnection object at 0x74bc87f0>: Failed to establish a new connection: [Errno 111] Connection refused'))
mai 14 00:02:53 raspberrypi mainApp.py[2526]: [DataToLocalInfluxDB] : data not saved, timeout ! HTTPConnectionPool(host='localhost', port=8086): Max retries exceeded with url: /write?db=SensorData (Caused by NewConnectionError('<urllib3.connection.HTTPConnection object at 0x74be5330>: Failed to establish a new connection: [Errno 111] Connection refused'))
mai 14 00:02:53 raspberrypi mainApp.py[2526]: [DataToLocalInfluxDB] : data not saved, timeout ! HTTPConnectionPool(host='localhost', port=8086): Max retries exceeded with url: /write?db=SensorData (Caused by NewConnectionError('<urllib3.connection.HTTPConnection object at 0x74be5770>: Failed to establish a new connection: [Errno 111] Connection refused'))
mai 14 00:02:53 raspberrypi mainApp.py[2526]: [DataToLocalInfluxDB] : data not saved, timeout ! HTTPConnectionPool(host='localhost', port=8086): Max retries exceeded with url: /write?db=SensorData (Caused by NewConnectionError('<urllib3.connection.HTTPConnection object at 0x74be5690>: Failed to establish a new connection: [Errno 111] Connection refused'))
mai 14 00:02:53 raspberrypi mainApp.py[2526]: [DataToLocalInfluxDB] : data not saved, timeout ! HTTPConnectionPool(host='localhost', port=8086): Max retries exceeded with url: /write?db=SensorData (Caused by NewConnectionError('<urllib3.connection.HTTPConnection object at 0x74be52b0>: Failed to establish a new connection: [Errno 111] Connection refused'))
mai 14 00:02:54 raspberrypi mainApp.py[2526]: [DataToLocalInfluxDB] : data not saved, timeout ! HTTPConnectionPool(host='localhost', port=8086): Max retries exceeded with url: /write?db=SensorData (Caused by NewConnectionError('<urllib3.connection.HTTPConnection object at 0x74be5d30>: Failed to establish a new connection: [Errno 111] Connection refused'))
mai 14 00:02:54 raspberrypi mainApp.py[2526]: [DataToLocalInfluxDB] : data not saved, timeout ! HTTPConnectionPool(host='localhost', port=8086): Max retries exceeded with url: /write?db=SensorData (Caused by NewConnectionError('<urllib3.connection.HTTPConnection object at 0x74be5c70>: Failed to establish a new connection: [Errno 111] Connection refused'))
mai 14 00:02:54 raspberrypi mainApp.py[2526]: [DataToLocalInfluxDB] : data not saved, timeout ! HTTPConnectionPool(host='localhost', port=8086): Max retries exceeded with url: /write?db=SensorData (Caused by NewConnectionError('<urllib3.connection.HTTPConnection object at 0x74bc81b0>: Failed to establish a new connection: [Errno 111] Connection refused'))
mai 14 00:02:54 raspberrypi mainApp.py[2526]: [DataToLocalInfluxDB] : data not saved, timeout ! HTTPConnectionPool(host='localhost', port=8086): Max retries exceeded with url: /write?db=SensorData (Caused by NewConnectionError('<urllib3.connection.HTTPConnection object at 0x74bc81f0>: Failed to establish a new connection: [Errno 111] Connection refused'))
mai 14 00:02:54 raspberrypi mainApp.py[2526]: [DataToLocalInfluxDB] : data not saved, timeout ! HTTPConnectionPool(host='localhost', port=8086): Max retries exceeded with url: /write?db=SensorData (Caused by NewConnectionError('<urllib3.connection.HTTPConnection object at 0x74b776f0>: Failed to establish a new connection: [Errno 111] Connection refused'))
mai 14 00:02:54 raspberrypi mainApp.py[2526]: [DataToLocalInfluxDB] : data not saved, timeout ! HTTPConnectionPool(host='localhost', port=8086): Max retries exceeded with url: /write?db=SensorData (Caused by NewConnectionError('<urllib3.connection.HTTPConnection object at 0x74bc8310>: Failed to establish a new connection: [Errno 111] Connection refused'))
mai 14 00:02:54 raspberrypi mainApp.py[2526]: [DataToLocalInfluxDB] : data not saved, timeout ! HTTPConnectionPool(host='localhost', port=8086): Max retries exceeded with url: /write?db=SensorData (Caused by NewConnectionError('<urllib3.connection.HTTPConnection object at 0x74bc8390>: Failed to establish a new connection: [Errno 111] Connection refused'))
mai 14 00:02:54 raspberrypi mainApp.py[2526]: [DataToLocalInfluxDB] : data not saved, timeout ! HTTPConnectionPool(host='localhost', port=8086): Max retries exceeded with url: /write?db=SensorData (Caused by NewConnectionError('<urllib3.connection.HTTPConnection object at 0x74be5ab0>: Failed to establish a new connection: [Errno 111] Connection refused'))
mai 14 00:02:54 raspberrypi mainApp.py[2526]: [DataToLocalInfluxDB] : data not saved, timeout ! HTTPConnectionPool(host='localhost', port=8086): Max retries exceeded with url: /write?db=SensorData (Caused by NewConnectionError('<urllib3.connection.HTTPConnection object at 0x74be5db0>: Failed to establish a new connection: [Errno 111] Connection refused'))
mai 14 00:02:54 raspberrypi mainApp.py[2526]: [DataToLocalInfluxDB] : data not saved, timeout ! HTTPConnectionPool(host='localhost', port=8086): Max retries exceeded with url: /write?db=SensorData (Caused by NewConnectionError('<urllib3.connection.HTTPConnection object at 0x74be5830>: Failed to establish a new connection: [Errno 111] Connection refused'))
mai 14 00:02:54 raspberrypi mainApp.py[2526]: [DataToLocalInfluxDB] : data not saved, timeout ! HTTPConnectionPool(host='localhost', port=8086): Max retries exceeded with url: /write?db=SensorData (Caused by NewConnectionError('<urllib3.connection.HTTPConnection object at 0x74be52f0>: Failed to establish a new connection: [Errno 111] Connection refused'))
mai 14 00:02:54 raspberrypi mainApp.py[2526]: [DataToLocalInfluxDB] : data not saved, timeout ! HTTPConnectionPool(host='localhost', port=8086): Max retries exceeded with url: /write?db=SensorData (Caused by NewConnectionError('<urllib3.connection.HTTPConnection object at 0x74be5b10>: Failed to establish a new connection: [Errno 111] Connection refused'))
mai 14 00:02:54 raspberrypi mainApp.py[2526]: [DataToLocalInfluxDB] : data not saved, timeout ! HTTPConnectionPool(host='localhost', port=8086): Max retries exceeded with url: /write?db=SensorData (Caused by NewConnectionError('<urllib3.connection.HTTPConnection object at 0x74be5410>: Failed to establish a new connection: [Errno 111] Connection refused'))
mai 14 00:02:54 raspberrypi mainApp.py[2526]: [DataToLocalInfluxDB] : data not saved, timeout ! HTTPConnectionPool(host='localhost', port=8086): Max retries exceeded with url: /write?db=SensorData (Caused by NewConnectionError('<urllib3.connection.HTTPConnection object at 0x74bc8bf0>: Failed to establish a new connection: [Errno 111] Connection refused'))
mai 14 00:02:54 raspberrypi mainApp.py[2526]: [DataToLocalInfluxDB] : data not saved, timeout ! HTTPConnectionPool(host='localhost', port=8086): Max retries exceeded with url: /write?db=SensorData (Caused by NewConnectionError('<urllib3.connection.HTTPConnection object at 0x74bc8490>: Failed to establish a new connection: [Errno 111] Connection refused'))
mai 14 00:02:54 raspberrypi mainApp.py[2526]: [DataToLocalInfluxDB] : data not saved, timeout ! HTTPConnectionPool(host='localhost', port=8086): Max retries exceeded with url: /write?db=SensorData (Caused by NewConnectionError('<urllib3.connection.HTTPConnection object at 0x74b77f90>: Failed to establish a new connection: [Errno 111] Connection refused'))
mai 14 00:02:54 raspberrypi mainApp.py[2526]: [DataToLocalInfluxDB] : data not saved, timeout ! HTTPConnectionPool(host='localhost', port=8086): Max retries exceeded with url: /write?db=SensorData (Caused by NewConnectionError('<urllib3.connection.HTTPConnection object at 0x74bc8290>: Failed to establish a new connection: [Errno 111] Connection refused'))
mai 14 00:02:55 raspberrypi mainApp.py[2526]: [DataToLocalInfluxDB] : data not saved, timeout ! HTTPConnectionPool(host='localhost', port=8086): Max retries exceeded with url: /write?db=SensorData (Caused by NewConnectionError('<urllib3.connection.HTTPConnection object at 0x74bc87f0>: Failed to establish a new connection: [Errno 111] Connection refused'))
mai 14 00:02:55 raspberrypi mainApp.py[2526]: [DataToLocalInfluxDB] : data not saved, timeout ! HTTPConnectionPool(host='localhost', port=8086): Max retries exceeded with url: /write?db=SensorData (Caused by NewConnectionError('<urllib3.connection.HTTPConnection object at 0x74bc8f10>: Failed to establish a new connection: [Errno 111] Connection refused'))
mai 14 00:02:55 raspberrypi mainApp.py[2526]: [DataToLocalInfluxDB] : data not saved, timeout ! HTTPConnectionPool(host='localhost', port=8086): Max retries exceeded with url: /write?db=SensorData (Caused by NewConnectionError('<urllib3.connection.HTTPConnection object at 0x74be5950>: Failed to establish a new connection: [Errno 111] Connection refused'))
mai 14 00:02:55 raspberrypi mainApp.py[2526]: [DataToLocalInfluxDB] : data not saved, timeout ! HTTPConnectionPool(host='localhost', port=8086): Max retries exceeded with url: /write?db=SensorData (Caused by NewConnectionError('<urllib3.connection.HTTPConnection object at 0x74be5910>: Failed to establish a new connection: [Errno 111] Connection refused'))
mai 14 00:02:55 raspberrypi mainApp.py[2526]: [DataToLocalInfluxDB] : data not saved, timeout ! HTTPConnectionPool(host='localhost', port=8086): Max retries exceeded with url: /write?db=SensorData (Caused by NewConnectionError('<urllib3.connection.HTTPConnection object at 0x74b77ef0>: Failed to establish a new connection: [Errno 111] Connection refused'))
mai 14 00:02:55 raspberrypi mainApp.py[2526]: [DataToLocalInfluxDB] : data not saved, timeout ! HTTPConnectionPool(host='localhost', port=8086): Max retries exceeded with url: /write?db=SensorData (Caused by NewConnectionError('<urllib3.connection.HTTPConnection object at 0x74be5f50>: Failed to establish a new connection: [Errno 111] Connection refused'))
mai 14 00:02:55 raspberrypi mainApp.py[2526]: [DataToLocalInfluxDB] : data not saved, timeout ! HTTPConnectionPool(host='localhost', port=8086): Max retries exceeded with url: /write?db=SensorData (Caused by NewConnectionError('<urllib3.connection.HTTPConnection object at 0x74be57f0>: Failed to establish a new connection: [Errno 111] Connection refused'))
mai 14 00:02:55 raspberrypi mainApp.py[2526]: [DataToLocalInfluxDB] : data not saved, timeout ! HTTPConnectionPool(host='localhost', port=8086): Max retries exceeded with url: /write?db=SensorData (Caused by NewConnectionError('<urllib3.connection.HTTPConnection object at 0x74bc8f30>: Failed to establish a new connection: [Errno 111] Connection refused'))
mai 14 00:02:55 raspberrypi mainApp.py[2526]: [DataToLocalInfluxDB] : data not saved, timeout ! HTTPConnectionPool(host='localhost', port=8086): Max retries exceeded with url: /write?db=SensorData (Caused by NewConnectionError('<urllib3.connection.HTTPConnection object at 0x74bc88d0>: Failed to establish a new connection: [Errno 111] Connection refused'))
mai 14 00:02:55 raspberrypi mainApp.py[2526]: [DataToLocalInfluxDB] : data not saved, timeout ! HTTPConnectionPool(host='localhost', port=8086): Max retries exceeded with url: /write?db=SensorData (Caused by NewConnectionError('<urllib3.connection.HTTPConnection object at 0x74bc82f0>: Failed to establish a new connection: [Errno 111] Connection refused'))
mai 14 00:02:55 raspberrypi mainApp.py[2526]: [DataToLocalInfluxDB] : data not saved, timeout ! HTTPConnectionPool(host='localhost', port=8086): Max retries exceeded with url: /write?db=SensorData (Caused by NewConnectionError('<urllib3.connection.HTTPConnection object at 0x74bc82f0>: Failed to establish a new connection: [Errno 111] Connection refused'))
mai 14 00:02:55 raspberrypi mainApp.py[2526]: [DataToLocalInfluxDB] : data not saved, timeout ! HTTPConnectionPool(host='localhost', port=8086): Max retries exceeded with url: /write?db=SensorData (Caused by NewConnectionError('<urllib3.connection.HTTPConnection object at 0x74bc8150>: Failed to establish a new connection: [Errno 111] Connection refused'))
mai 14 00:02:55 raspberrypi mainApp.py[2526]: [DataToLocalInfluxDB] : data not saved, timeout ! HTTPConnectionPool(host='localhost', port=8086): Max retries exceeded with url: /write?db=SensorData (Caused by NewConnectionError('<urllib3.connection.HTTPConnection object at 0x74be5330>: Failed to establish a new connection: [Errno 111] Connection refused'))
mai 14 00:02:55 raspberrypi mainApp.py[2526]: [DataToLocalInfluxDB] : data not saved, timeout ! HTTPConnectionPool(host='localhost', port=8086): Max retries exceeded with url: /write?db=SensorData (Caused by NewConnectionError('<urllib3.connection.HTTPConnection object at 0x74be57f0>: Failed to establish a new connection: [Errno 111] Connection refused'))
mai 14 00:02:55 raspberrypi mainApp.py[2526]: [DataToLocalInfluxDB] : data not saved, timeout ! HTTPConnectionPool(host='localhost', port=8086): Max retries exceeded with url: /write?db=SensorData (Caused by NewConnectionError('<urllib3.connection.HTTPConnection object at 0x74be5d30>: Failed to establish a new connection: [Errno 111] Connection refused'))
mai 14 00:02:55 raspberrypi mainApp.py[2526]: [DataToLocalInfluxDB] : data not saved, timeout ! HTTPConnectionPool(host='localhost', port=8086): Max retries exceeded with url: /write?db=SensorData (Caused by NewConnectionError('<urllib3.connection.HTTPConnection object at 0x74b77670>: Failed to establish a new connection: [Errno 111] Connection refused'))
mai 14 00:02:55 raspberrypi mainApp.py[2526]: [DataToLocalInfluxDB] : data not saved, timeout ! HTTPConnectionPool(host='localhost', port=8086): Max retries exceeded with url: /write?db=SensorData (Caused by NewConnectionError('<urllib3.connection.HTTPConnection object at 0x74be59f0>: Failed to establish a new connection: [Errno 111] Connection refused'))
mai 14 00:02:55 raspberrypi mainApp.py[2526]: [DataToLocalInfluxDB] : data not saved, timeout ! HTTPConnectionPool(host='localhost', port=8086): Max retries exceeded with url: /write?db=SensorData (Caused by NewConnectionError('<urllib3.connection.HTTPConnection object at 0x74be5b50>: Failed to establish a new connection: [Errno 111] Connection refused'))
mai 14 00:02:56 raspberrypi mainApp.py[2526]: [DataToLocalInfluxDB] : data not saved, timeout ! HTTPConnectionPool(host='localhost', port=8086): Max retries exceeded with url: /write?db=SensorData (Caused by NewConnectionError('<urllib3.connection.HTTPConnection object at 0x74bc8170>: Failed to establish a new connection: [Errno 111] Connection refused'))
mai 14 00:02:56 raspberrypi mainApp.py[2526]: [DataToLocalInfluxDB] : data not saved, timeout ! HTTPConnectionPool(host='localhost', port=8086): Max retries exceeded with url: /write?db=SensorData (Caused by NewConnectionError('<urllib3.connection.HTTPConnection object at 0x74bc8750>: Failed to establish a new connection: [Errno 111] Connection refused'))
mai 14 00:02:56 raspberrypi mainApp.py[2526]: [DataToLocalInfluxDB] : data not saved, timeout ! HTTPConnectionPool(host='localhost', port=8086): Max retries exceeded with url: /write?db=SensorData (Caused by NewConnectionError('<urllib3.connection.HTTPConnection object at 0x74bc8270>: Failed to establish a new connection: [Errno 111] Connection refused'))
mai 14 00:02:56 raspberrypi mainApp.py[2526]: [DataToLocalInfluxDB] : data not saved, timeout ! HTTPConnectionPool(host='localhost', port=8086): Max retries exceeded with url: /write?db=SensorData (Caused by NewConnectionError('<urllib3.connection.HTTPConnection object at 0x74bc8fd0>: Failed to establish a new connection: [Errno 111] Connection refused'))
mai 14 00:02:56 raspberrypi mainApp.py[2526]: [DataToLocalInfluxDB] : data not saved, timeout ! HTTPConnectionPool(host='localhost', port=8086): Max retries exceeded with url: /write?db=SensorData (Caused by NewConnectionError('<urllib3.connection.HTTPConnection object at 0x74bc8230>: Failed to establish a new connection: [Errno 111] Connection refused'))
mai 14 00:02:56 raspberrypi mainApp.py[2526]: [DataToLocalInfluxDB] : data not saved, timeout ! HTTPConnectionPool(host='localhost', port=8086): Max retries exceeded with url: /write?db=SensorData (Caused by NewConnectionError('<urllib3.connection.HTTPConnection object at 0x74bc8f10>: Failed to establish a new connection: [Errno 111] Connection refused'))
mai 14 00:02:56 raspberrypi mainApp.py[2526]: [DataToLocalInfluxDB] : data not saved, timeout ! HTTPConnectionPool(host='localhost', port=8086): Max retries exceeded with url: /write?db=SensorData (Caused by NewConnectionError('<urllib3.connection.HTTPConnection object at 0x74be54f0>: Failed to establish a new connection: [Errno 111] Connection refused'))
mai 14 00:02:56 raspberrypi mainApp.py[2526]: [DataToLocalInfluxDB] : data not saved, timeout ! HTTPConnectionPool(host='localhost', port=8086): Max retries exceeded with url: /write?db=SensorData (Caused by NewConnectionError('<urllib3.connection.HTTPConnection object at 0x74be5770>: Failed to establish a new connection: [Errno 111] Connection refused'))
mai 14 00:02:56 raspberrypi mainApp.py[2526]: [DataToLocalInfluxDB] : data not saved, timeout ! HTTPConnectionPool(host='localhost', port=8086): Max retries exceeded with url: /write?db=SensorData (Caused by NewConnectionError('<urllib3.connection.HTTPConnection object at 0x74b77630>: Failed to establish a new connection: [Errno 111] Connection refused'))
mai 14 00:02:56 raspberrypi mainApp.py[2526]: [DataToLocalInfluxDB] : data not saved, timeout ! HTTPConnectionPool(host='localhost', port=8086): Max retries exceeded with url: /write?db=SensorData (Caused by NewConnectionError('<urllib3.connection.HTTPConnection object at 0x74be5990>: Failed to establish a new connection: [Errno 111] Connection refused'))
mai 14 00:02:56 raspberrypi mainApp.py[2526]: [DataToLocalInfluxDB] : data not saved, timeout ! HTTPConnectionPool(host='localhost', port=8086): Max retries exceeded with url: /write?db=SensorData (Caused by NewConnectionError('<urllib3.connection.HTTPConnection object at 0x74be5b70>: Failed to establish a new connection: [Errno 111] Connection refused'))
mai 14 00:02:56 raspberrypi mainApp.py[2526]: [DataToLocalInfluxDB] : data not saved, timeout ! HTTPConnectionPool(host='localhost', port=8086): Max retries exceeded with url: /write?db=SensorData (Caused by NewConnectionError('<urllib3.connection.HTTPConnection object at 0x74bc8850>: Failed to establish a new connection: [Errno 111] Connection refused'))
mai 14 00:02:56 raspberrypi mainApp.py[2526]: [DataToLocalInfluxDB] : data not saved, timeout ! HTTPConnectionPool(host='localhost', port=8086): Max retries exceeded with url: /write?db=SensorData (Caused by NewConnectionError('<urllib3.connection.HTTPConnection object at 0x74bc89b0>: Failed to establish a new connection: [Errno 111] Connection refused'))
mai 14 00:02:56 raspberrypi mainApp.py[2526]: [DataToLocalInfluxDB] : data not saved, timeout ! HTTPConnectionPool(host='localhost', port=8086): Max retries exceeded with url: /write?db=SensorData (Caused by NewConnectionError('<urllib3.connection.HTTPConnection object at 0x74bc8f50>: Failed to establish a new connection: [Errno 111] Connection refused'))
mai 14 00:02:57 raspberrypi mainApp.py[2526]: [DataToLocalInfluxDB] : data not saved, timeout ! HTTPConnectionPool(host='localhost', port=8086): Max retries exceeded with url: /write?db=SensorData (Caused by NewConnectionError('<urllib3.connection.HTTPConnection object at 0x74bc8fb0>: Failed to establish a new connection: [Errno 111] Connection refused'))
mai 14 00:02:57 raspberrypi mainApp.py[2526]: [DataToLocalInfluxDB] : data not saved, timeout ! HTTPConnectionPool(host='localhost', port=8086): Max retries exceeded with url: /write?db=SensorData (Caused by NewConnectionError('<urllib3.connection.HTTPConnection object at 0x74bc8870>: Failed to establish a new connection: [Errno 111] Connection refused'))
mai 14 00:02:57 raspberrypi mainApp.py[2526]: [DataToLocalInfluxDB] : data not saved, timeout ! HTTPConnectionPool(host='localhost', port=8086): Max retries exceeded with url: /write?db=SensorData (Caused by NewConnectionError('<urllib3.connection.HTTPConnection object at 0x74bc83b0>: Failed to establish a new connection: [Errno 111] Connection refused'))
mai 14 00:02:57 raspberrypi mainApp.py[2526]: [DataToLocalInfluxDB] : data not saved, timeout ! HTTPConnectionPool(host='localhost', port=8086): Max retries exceeded with url: /write?db=SensorData (Caused by NewConnectionError('<urllib3.connection.HTTPConnection object at 0x74be54d0>: Failed to establish a new connection: [Errno 111] Connection refused'))
mai 14 00:02:57 raspberrypi mainApp.py[2526]: [DataToLocalInfluxDB] : data not saved, timeout ! HTTPConnectionPool(host='localhost', port=8086): Max retries exceeded with url: /write?db=SensorData (Caused by NewConnectionError('<urllib3.connection.HTTPConnection object at 0x74be51b0>: Failed to establish a new connection: [Errno 111] Connection refused'))
mai 14 00:02:57 raspberrypi mainApp.py[2526]: [DataToLocalInfluxDB] : data not saved, timeout ! HTTPConnectionPool(host='localhost', port=8086): Max retries exceeded with url: /write?db=SensorData (Caused by NewConnectionError('<urllib3.connection.HTTPConnection object at 0x74b770d0>: Failed to establish a new connection: [Errno 111] Connection refused'))
mai 14 00:02:57 raspberrypi mainApp.py[2526]: [DataToLocalInfluxDB] : data not saved, timeout ! HTTPConnectionPool(host='localhost', port=8086): Max retries exceeded with url: /write?db=SensorData (Caused by NewConnectionError('<urllib3.connection.HTTPConnection object at 0x74be52b0>: Failed to establish a new connection: [Errno 111] Connection refused'))
mai 14 00:02:57 raspberrypi mainApp.py[2526]: [DataToLocalInfluxDB] : data not saved, timeout ! HTTPConnectionPool(host='localhost', port=8086): Max retries exceeded with url: /write?db=SensorData (Caused by NewConnectionError('<urllib3.connection.HTTPConnection object at 0x74be59f0>: Failed to establish a new connection: [Errno 111] Connection refused'))
mai 14 00:02:57 raspberrypi mainApp.py[2526]: [DataToLocalInfluxDB] : data not saved, timeout ! HTTPConnectionPool(host='localhost', port=8086): Max retries exceeded with url: /write?db=SensorData (Caused by NewConnectionError('<urllib3.connection.HTTPConnection object at 0x74b77770>: Failed to establish a new connection: [Errno 111] Connection refused'))
mai 14 00:02:57 raspberrypi mainApp.py[2526]: [DataToLocalInfluxDB] : data not saved, timeout ! HTTPConnectionPool(host='localhost', port=8086): Max retries exceeded with url: /write?db=SensorData (Caused by NewConnectionError('<urllib3.connection.HTTPConnection object at 0x74bc8170>: Failed to establish a new connection: [Errno 111] Connection refused'))
mai 14 00:02:57 raspberrypi mainApp.py[2526]: [DataToLocalInfluxDB] : data not saved, timeout ! HTTPConnectionPool(host='localhost', port=8086): Max retries exceeded with url: /write?db=SensorData (Caused by NewConnectionError('<urllib3.connection.HTTPConnection object at 0x74bc8c70>: Failed to establish a new connection: [Errno 111] Connection refused'))
mai 14 00:02:57 raspberrypi mainApp.py[2526]: [DataToLocalInfluxDB] : data not saved, timeout ! HTTPConnectionPool(host='localhost', port=8086): Max retries exceeded with url: /write?db=SensorData (Caused by NewConnectionError('<urllib3.connection.HTTPConnection object at 0x74b77410>: Failed to establish a new connection: [Errno 111] Connection refused'))
mai 14 00:02:57 raspberrypi mainApp.py[2526]: [DataToLocalInfluxDB] : data not saved, timeout ! HTTPConnectionPool(host='localhost', port=8086): Max retries exceeded with url: /write?db=SensorData (Caused by NewConnectionError('<urllib3.connection.HTTPConnection object at 0x74be5fd0>: Failed to establish a new connection: [Errno 111] Connection refused'))
mai 14 00:02:57 raspberrypi mainApp.py[2526]: [DataToLocalInfluxDB] : data not saved, timeout ! HTTPConnectionPool(host='localhost', port=8086): Max retries exceeded with url: /write?db=SensorData (Caused by NewConnectionError('<urllib3.connection.HTTPConnection object at 0x74be5c70>: Failed to establish a new connection: [Errno 111] Connection refused'))
mai 14 00:02:58 raspberrypi mainApp.py[2526]: [DataToLocalInfluxDB] : data not saved, timeout ! HTTPConnectionPool(host='localhost', port=8086): Max retries exceeded with url: /write?db=SensorData (Caused by NewConnectionError('<urllib3.connection.HTTPConnection object at 0x74be59b0>: Failed to establish a new connection: [Errno 111] Connection refused'))
mai 14 00:02:58 raspberrypi mainApp.py[2526]: [DataToLocalInfluxDB] : data not saved, timeout ! HTTPConnectionPool(host='localhost', port=8086): Max retries exceeded with url: /write?db=SensorData (Caused by NewConnectionError('<urllib3.connection.HTTPConnection object at 0x74bc8350>: Failed to establish a new connection: [Errno 111] Connection refused'))
mai 14 00:02:58 raspberrypi mainApp.py[2526]: [DataToLocalInfluxDB] : data not saved, timeout ! HTTPConnectionPool(host='localhost', port=8086): Max retries exceeded with url: /write?db=SensorData (Caused by NewConnectionError('<urllib3.connection.HTTPConnection object at 0x74bc8af0>: Failed to establish a new connection: [Errno 111] Connection refused'))
mai 14 00:02:58 raspberrypi mainApp.py[2526]: [DataToLocalInfluxDB] : data not saved, timeout ! HTTPConnectionPool(host='localhost', port=8086): Max retries exceeded with url: /write?db=SensorData (Caused by NewConnectionError('<urllib3.connection.HTTPConnection object at 0x74be5ff0>: Failed to establish a new connection: [Errno 111] Connection refused'))
mai 14 00:02:58 raspberrypi mainApp.py[2526]: [DataToLocalInfluxDB] : data not saved, timeout ! HTTPConnectionPool(host='localhost', port=8086): Max retries exceeded with url: /write?db=SensorData (Caused by NewConnectionError('<urllib3.connection.HTTPConnection object at 0x74be5770>: Failed to establish a new connection: [Errno 111] Connection refused'))
mai 14 00:02:58 raspberrypi mainApp.py[2526]: [DataToLocalInfluxDB] : data not saved, timeout ! HTTPConnectionPool(host='localhost', port=8086): Max retries exceeded with url: /write?db=SensorData (Caused by NewConnectionError('<urllib3.connection.HTTPConnection object at 0x74be57f0>: Failed to establish a new connection: [Errno 111] Connection refused'))
mai 14 00:02:58 raspberrypi mainApp.py[2526]: [DataToLocalInfluxDB] : data not saved, timeout ! HTTPConnectionPool(host='localhost', port=8086): Max retries exceeded with url: /write?db=SensorData (Caused by NewConnectionError('<urllib3.connection.HTTPConnection object at 0x74b776f0>: Failed to establish a new connection: [Errno 111] Connection refused'))
mai 14 00:02:58 raspberrypi mainApp.py[2526]: [DataToLocalInfluxDB] : data not saved, timeout ! HTTPConnectionPool(host='localhost', port=8086): Max retries exceeded with url: /write?db=SensorData (Caused by NewConnectionError('<urllib3.connection.HTTPConnection object at 0x74bc8950>: Failed to establish a new connection: [Errno 111] Connection refused'))
mai 14 00:02:58 raspberrypi mainApp.py[2526]: [DataToLocalInfluxDB] : data not saved, timeout ! HTTPConnectionPool(host='localhost', port=8086): Max retries exceeded with url: /write?db=SensorData (Caused by NewConnectionError('<urllib3.connection.HTTPConnection object at 0x75db3e30>: Failed to establish a new connection: [Errno 111] Connection refused'))
mai 14 00:02:58 raspberrypi mainApp.py[2526]: [DataToLocalInfluxDB] : data not saved, timeout ! HTTPConnectionPool(host='localhost', port=8086): Max retries exceeded with url: /write?db=SensorData (Caused by NewConnectionError('<urllib3.connection.HTTPConnection object at 0x74bc8390>: Failed to establish a new connection: [Errno 111] Connection refused'))
mai 14 00:02:58 raspberrypi mainApp.py[2526]: [DataToLocalInfluxDB] : data not saved, timeout ! HTTPConnectionPool(host='localhost', port=8086): Max retries exceeded with url: /write?db=SensorData (Caused by NewConnectionError('<urllib3.connection.HTTPConnection object at 0x74bc85f0>: Failed to establish a new connection: [Errno 111] Connection refused'))
mai 14 00:02:59 raspberrypi mainApp.py[2526]: [DataToLocalInfluxDB] : data not saved, timeout ! HTTPConnectionPool(host='localhost', port=8086): Max retries exceeded with url: /write?db=SensorData (Caused by NewConnectionError('<urllib3.connection.HTTPConnection object at 0x74b77e90>: Failed to establish a new connection: [Errno 111] Connection refused'))
mai 14 00:02:59 raspberrypi mainApp.py[2526]: [DataToLocalInfluxDB] : data not saved, timeout ! HTTPConnectionPool(host='localhost', port=8086): Max retries exceeded with url: /write?db=SensorData (Caused by NewConnectionError('<urllib3.connection.HTTPConnection object at 0x74b77eb0>: Failed to establish a new connection: [Errno 111] Connection refused'))
mai 14 00:02:59 raspberrypi mainApp.py[2526]: [DataToLocalInfluxDB] : data not saved, timeout ! HTTPConnectionPool(host='localhost', port=8086): Max retries exceeded with url: /write?db=SensorData (Caused by NewConnectionError('<urllib3.connection.HTTPConnection object at 0x74be53d0>: Failed to establish a new connection: [Errno 111] Connection refused'))
mai 14 00:02:59 raspberrypi mainApp.py[2526]: [DataToLocalInfluxDB] : data not saved, timeout ! HTTPConnectionPool(host='localhost', port=8086): Max retries exceeded with url: /write?db=SensorData (Caused by NewConnectionError('<urllib3.connection.HTTPConnection object at 0x74bc8770>: Failed to establish a new connection: [Errno 111] Connection refused'))
mai 14 00:02:59 raspberrypi mainApp.py[2526]: [DataToLocalInfluxDB] : data not saved, timeout ! HTTPConnectionPool(host='localhost', port=8086): Max retries exceeded with url: /write?db=SensorData (Caused by NewConnectionError('<urllib3.connection.HTTPConnection object at 0x74bc8570>: Failed to establish a new connection: [Errno 111] Connection refused'))
mai 14 00:02:59 raspberrypi mainApp.py[2526]: [DataToLocalInfluxDB] : data not saved, timeout ! HTTPConnectionPool(host='localhost', port=8086): Max retries exceeded with url: /write?db=SensorData (Caused by NewConnectionError('<urllib3.connection.HTTPConnection object at 0x74bc8190>: Failed to establish a new connection: [Errno 111] Connection refused'))
mai 14 00:02:59 raspberrypi mainApp.py[2526]: [DataToLocalInfluxDB] : data not saved, timeout ! HTTPConnectionPool(host='localhost', port=8086): Max retries exceeded with url: /write?db=SensorData (Caused by NewConnectionError('<urllib3.connection.HTTPConnection object at 0x74bc87f0>: Failed to establish a new connection: [Errno 111] Connection refused'))
mai 14 00:02:59 raspberrypi mainApp.py[2526]: [DataToLocalInfluxDB] : data not saved, timeout ! HTTPConnectionPool(host='localhost', port=8086): Max retries exceeded with url: /write?db=SensorData (Caused by NewConnectionError('<urllib3.connection.HTTPConnection object at 0x74bc8f50>: Failed to establish a new connection: [Errno 111] Connection refused'))
mai 14 00:02:59 raspberrypi mainApp.py[2526]: [DataToLocalInfluxDB] : data not saved, timeout ! HTTPConnectionPool(host='localhost', port=8086): Max retries exceeded with url: /write?db=SensorData (Caused by NewConnectionError('<urllib3.connection.HTTPConnection object at 0x74b77b30>: Failed to establish a new connection: [Errno 111] Connection refused'))
mai 14 00:02:59 raspberrypi mainApp.py[2526]: [DataToLocalInfluxDB] : data not saved, timeout ! HTTPConnectionPool(host='localhost', port=8086): Max retries exceeded with url: /write?db=SensorData (Caused by NewConnectionError('<urllib3.connection.HTTPConnection object at 0x74b77e90>: Failed to establish a new connection: [Errno 111] Connection refused'))
mai 14 00:02:59 raspberrypi mainApp.py[2526]: [DataToLocalInfluxDB] : data not saved, timeout ! HTTPConnectionPool(host='localhost', port=8086): Max retries exceeded with url: /write?db=SensorData (Caused by NewConnectionError('<urllib3.connection.HTTPConnection object at 0x74bc84f0>: Failed to establish a new connection: [Errno 111] Connection refused'))
mai 14 00:03:00 raspberrypi mainApp.py[2526]: [DataToLocalInfluxDB] : data not saved, timeout ! HTTPConnectionPool(host='localhost', port=8086): Max retries exceeded with url: /write?db=SensorData (Caused by NewConnectionError('<urllib3.connection.HTTPConnection object at 0x74bc8230>: Failed to establish a new connection: [Errno 111] Connection refused'))
mai 14 00:03:00 raspberrypi mainApp.py[2526]: [DataToLocalInfluxDB] : data not saved, timeout ! HTTPConnectionPool(host='localhost', port=8086): Max retries exceeded with url: /write?db=SensorData (Caused by NewConnectionError('<urllib3.connection.HTTPConnection object at 0x74bc8c10>: Failed to establish a new connection: [Errno 111] Connection refused'))
mai 14 00:03:00 raspberrypi mainApp.py[2526]: [DataToLocalInfluxDB] : data not saved, timeout ! HTTPConnectionPool(host='localhost', port=8086): Max retries exceeded with url: /write?db=SensorData (Caused by NewConnectionError('<urllib3.connection.HTTPConnection object at 0x74b77030>: Failed to establish a new connection: [Errno 111] Connection refused'))
mai 14 00:03:00 raspberrypi mainApp.py[2526]: [DataToLocalInfluxDB] : data not saved, timeout ! HTTPConnectionPool(host='localhost', port=8086): Max retries exceeded with url: /write?db=SensorData (Caused by NewConnectionError('<urllib3.connection.HTTPConnection object at 0x74b77c10>: Failed to establish a new connection: [Errno 111] Connection refused'))
mai 14 00:03:00 raspberrypi mainApp.py[2526]: [DataToLocalInfluxDB] : data not saved, timeout ! HTTPConnectionPool(host='localhost', port=8086): Max retries exceeded with url: /write?db=SensorData (Caused by NewConnectionError('<urllib3.connection.HTTPConnection object at 0x74bc8c70>: Failed to establish a new connection: [Errno 111] Connection refused'))
mai 14 00:03:00 raspberrypi mainApp.py[2526]: [DataToLocalInfluxDB] : data not saved, timeout ! HTTPConnectionPool(host='localhost', port=8086): Max retries exceeded with url: /write?db=SensorData (Caused by NewConnectionError('<urllib3.connection.HTTPConnection object at 0x74bc8390>: Failed to establish a new connection: [Errno 111] Connection refused'))
mai 14 00:03:00 raspberrypi mainApp.py[2526]: [DataToLocalInfluxDB] : data not saved, timeout ! HTTPConnectionPool(host='localhost', port=8086): Max retries exceeded with url: /write?db=SensorData (Caused by NewConnectionError('<urllib3.connection.HTTPConnection object at 0x74bc8850>: Failed to establish a new connection: [Errno 111] Connection refused'))
mai 14 00:03:00 raspberrypi mainApp.py[2526]: [DataToLocalInfluxDB] : data not saved, timeout ! HTTPConnectionPool(host='localhost', port=8086): Max retries exceeded with url: /write?db=SensorData (Caused by NewConnectionError('<urllib3.connection.HTTPConnection object at 0x74b77390>: Failed to establish a new connection: [Errno 111] Connection refused'))
mai 14 00:03:00 raspberrypi mainApp.py[2526]: [DataToLocalInfluxDB] : data not saved, timeout ! HTTPConnectionPool(host='localhost', port=8086): Max retries exceeded with url: /write?db=SensorData (Caused by NewConnectionError('<urllib3.connection.HTTPConnection object at 0x74b774d0>: Failed to establish a new connection: [Errno 111] Connection refused'))
mai 14 00:03:00 raspberrypi mainApp.py[2526]: [DataToLocalInfluxDB] : data not saved, timeout ! HTTPConnectionPool(host='localhost', port=8086): Max retries exceeded with url: /write?db=SensorData (Caused by NewConnectionError('<urllib3.connection.HTTPConnection object at 0x74b77b10>: Failed to establish a new connection: [Errno 111] Connection refused'))
mai 14 00:03:00 raspberrypi mainApp.py[2526]: [DataToLocalInfluxDB] : data not saved, timeout ! HTTPConnectionPool(host='localhost', port=8086): Max retries exceeded with url: /write?db=SensorData (Caused by NewConnectionError('<urllib3.connection.HTTPConnection object at 0x74b77650>: Failed to establish a new connection: [Errno 111] Connection refused'))
mai 14 00:03:00 raspberrypi mainApp.py[2526]: [DataToLocalInfluxDB] : data not saved, timeout ! HTTPConnectionPool(host='localhost', port=8086): Max retries exceeded with url: /write?db=SensorData (Caused by NewConnectionError('<urllib3.connection.HTTPConnection object at 0x74b77190>: Failed to establish a new connection: [Errno 111] Connection refused'))
mai 14 00:03:00 raspberrypi mainApp.py[2526]: [DataToLocalInfluxDB] : data not saved, timeout ! HTTPConnectionPool(host='localhost', port=8086): Max retries exceeded with url: /write?db=SensorData (Caused by NewConnectionError('<urllib3.connection.HTTPConnection object at 0x74bc8130>: Failed to establish a new connection: [Errno 111] Connection refused'))
mai 14 00:03:00 raspberrypi mainApp.py[2526]: [DataToLocalInfluxDB] : data not saved, timeout ! HTTPConnectionPool(host='localhost', port=8086): Max retries exceeded with url: /write?db=SensorData (Caused by NewConnectionError('<urllib3.connection.HTTPConnection object at 0x74bc8b90>: Failed to establish a new connection: [Errno 111] Connection refused'))
mai 14 00:03:00 raspberrypi mainApp.py[2526]: [DataToLocalInfluxDB] : data not saved, timeout ! HTTPConnectionPool(host='localhost', port=8086): Max retries exceeded with url: /write?db=SensorData (Caused by NewConnectionError('<urllib3.connection.HTTPConnection object at 0x74be5fb0>: Failed to establish a new connection: [Errno 111] Connection refused'))
mai 14 00:03:00 raspberrypi mainApp.py[2526]: [DataToLocalInfluxDB] : data not saved, timeout ! HTTPConnectionPool(host='localhost', port=8086): Max retries exceeded with url: /write?db=SensorData (Caused by NewConnectionError('<urllib3.connection.HTTPConnection object at 0x74bc8df0>: Failed to establish a new connection: [Errno 111] Connection refused'))
mai 14 00:03:01 raspberrypi mainApp.py[2526]: [DataToLocalInfluxDB] : data not saved, timeout ! HTTPConnectionPool(host='localhost', port=8086): Max retries exceeded with url: /write?db=SensorData (Caused by NewConnectionError('<urllib3.connection.HTTPConnection object at 0x74bc8f90>: Failed to establish a new connection: [Errno 111] Connection refused'))
mai 14 00:03:01 raspberrypi mainApp.py[2526]: [DataToLocalInfluxDB] : data not saved, timeout ! HTTPConnectionPool(host='localhost', port=8086): Max retries exceeded with url: /write?db=SensorData (Caused by NewConnectionError('<urllib3.connection.HTTPConnection object at 0x74bc89d0>: Failed to establish a new connection: [Errno 111] Connection refused'))
mai 14 00:03:01 raspberrypi mainApp.py[2526]: [DataToLocalInfluxDB] : data not saved, timeout ! HTTPConnectionPool(host='localhost', port=8086): Max retries exceeded with url: /write?db=SensorData (Caused by NewConnectionError('<urllib3.connection.HTTPConnection object at 0x74b77c10>: Failed to establish a new connection: [Errno 111] Connection refused'))
mai 14 00:03:01 raspberrypi mainApp.py[2526]: [DataToLocalInfluxDB] : data not saved, timeout ! HTTPConnectionPool(host='localhost', port=8086): Max retries exceeded with url: /write?db=SensorData (Caused by NewConnectionError('<urllib3.connection.HTTPConnection object at 0x74b77ab0>: Failed to establish a new connection: [Errno 111] Connection refused'))
mai 14 00:03:01 raspberrypi mainApp.py[2526]: [DataToLocalInfluxDB] : data not saved, timeout ! HTTPConnectionPool(host='localhost', port=8086): Max retries exceeded with url: /write?db=SensorData (Caused by NewConnectionError('<urllib3.connection.HTTPConnection object at 0x74b77050>: Failed to establish a new connection: [Errno 111] Connection refused'))
mai 14 00:03:01 raspberrypi mainApp.py[2526]: [DataToLocalInfluxDB] : data not saved, timeout ! HTTPConnectionPool(host='localhost', port=8086): Max retries exceeded with url: /write?db=SensorData (Caused by NewConnectionError('<urllib3.connection.HTTPConnection object at 0x74b77830>: Failed to establish a new connection: [Errno 111] Connection refused'))
mai 14 00:03:01 raspberrypi mainApp.py[2526]: [DataToLocalInfluxDB] : data not saved, timeout ! HTTPConnectionPool(host='localhost', port=8086): Max retries exceeded with url: /write?db=SensorData (Caused by NewConnectionError('<urllib3.connection.HTTPConnection object at 0x74b77a30>: Failed to establish a new connection: [Errno 111] Connection refused'))
mai 14 00:03:01 raspberrypi mainApp.py[2526]: [DataToLocalInfluxDB] : data not saved, timeout ! HTTPConnectionPool(host='localhost', port=8086): Max retries exceeded with url: /write?db=SensorData (Caused by NewConnectionError('<urllib3.connection.HTTPConnection object at 0x74bc8a70>: Failed to establish a new connection: [Errno 111] Connection refused'))
mai 14 00:03:01 raspberrypi mainApp.py[2526]: [DataToLocalInfluxDB] : data not saved, timeout ! HTTPConnectionPool(host='localhost', port=8086): Max retries exceeded with url: /write?db=SensorData (Caused by NewConnectionError('<urllib3.connection.HTTPConnection object at 0x74bc87f0>: Failed to establish a new connection: [Errno 111] Connection refused'))
mai 14 00:03:01 raspberrypi mainApp.py[2526]: [DataToLocalInfluxDB] : data not saved, timeout ! HTTPConnectionPool(host='localhost', port=8086): Max retries exceeded with url: /write?db=SensorData (Caused by NewConnectionError('<urllib3.connection.HTTPConnection object at 0x74be5110>: Failed to establish a new connection: [Errno 111] Connection refused'))
mai 14 00:03:01 raspberrypi mainApp.py[2526]: [DataToLocalInfluxDB] : data not saved, timeout ! HTTPConnectionPool(host='localhost', port=8086): Max retries exceeded with url: /write?db=SensorData (Caused by NewConnectionError('<urllib3.connection.HTTPConnection object at 0x74bc8590>: Failed to establish a new connection: [Errno 111] Connection refused'))
mai 14 00:03:01 raspberrypi mainApp.py[2526]: [DataToLocalInfluxDB] : data not saved, timeout ! HTTPConnectionPool(host='localhost', port=8086): Max retries exceeded with url: /write?db=SensorData (Caused by NewConnectionError('<urllib3.connection.HTTPConnection object at 0x74bc82b0>: Failed to establish a new connection: [Errno 111] Connection refused'))
mai 14 00:03:01 raspberrypi mainApp.py[2526]: [DataToLocalInfluxDB] : data not saved, timeout ! HTTPConnectionPool(host='localhost', port=8086): Max retries exceeded with url: /write?db=SensorData (Caused by NewConnectionError('<urllib3.connection.HTTPConnection object at 0x75db3ef0>: Failed to establish a new connection: [Errno 111] Connection refused'))
mai 14 00:03:01 raspberrypi mainApp.py[2526]: [DataToLocalInfluxDB] : data not saved, timeout ! HTTPConnectionPool(host='localhost', port=8086): Max retries exceeded with url: /write?db=SensorData (Caused by NewConnectionError('<urllib3.connection.HTTPConnection object at 0x74b77930>: Failed to establish a new connection: [Errno 111] Connection refused'))
mai 14 00:03:01 raspberrypi mainApp.py[2526]: [DataToLocalInfluxDB] : data not saved, timeout ! HTTPConnectionPool(host='localhost', port=8086): Max retries exceeded with url: /write?db=SensorData (Caused by NewConnectionError('<urllib3.connection.HTTPConnection object at 0x74b77570>: Failed to establish a new connection: [Errno 111] Connection refused'))
mai 14 00:03:01 raspberrypi mainApp.py[2526]: [DataToLocalInfluxDB] : data not saved, timeout ! HTTPConnectionPool(host='localhost', port=8086): Max retries exceeded with url: /write?db=SensorData (Caused by NewConnectionError('<urllib3.connection.HTTPConnection object at 0x74be5550>: Failed to establish a new connection: [Errno 111] Connection refused'))
mai 14 00:03:01 raspberrypi mainApp.py[2526]: [DataToLocalInfluxDB] : data not saved, timeout ! HTTPConnectionPool(host='localhost', port=8086): Max retries exceeded with url: /write?db=SensorData (Caused by NewConnectionError('<urllib3.connection.HTTPConnection object at 0x74b77170>: Failed to establish a new connection: [Errno 111] Connection refused'))
mai 14 00:03:01 raspberrypi mainApp.py[2526]: [DataToLocalInfluxDB] : data not saved, timeout ! HTTPConnectionPool(host='localhost', port=8086): Max retries exceeded with url: /write?db=SensorData (Caused by NewConnectionError('<urllib3.connection.HTTPConnection object at 0x74b77730>: Failed to establish a new connection: [Errno 111] Connection refused'))
mai 14 00:03:02 raspberrypi mainApp.py[2526]: [DataToLocalInfluxDB] : data not saved, timeout ! HTTPConnectionPool(host='localhost', port=8086): Max retries exceeded with url: /write?db=SensorData (Caused by NewConnectionError('<urllib3.connection.HTTPConnection object at 0x74bc8870>: Failed to establish a new connection: [Errno 111] Connection refused'))
mai 14 00:03:02 raspberrypi mainApp.py[2526]: [DataToLocalInfluxDB] : data not saved, timeout ! HTTPConnectionPool(host='localhost', port=8086): Max retries exceeded with url: /write?db=SensorData (Caused by NewConnectionError('<urllib3.connection.HTTPConnection object at 0x74bc8450>: Failed to establish a new connection: [Errno 111] Connection refused'))
mai 14 00:03:02 raspberrypi mainApp.py[2526]: [DataToLocalInfluxDB] : data not saved, timeout ! HTTPConnectionPool(host='localhost', port=8086): Max retries exceeded with url: /write?db=SensorData (Caused by NewConnectionError('<urllib3.connection.HTTPConnection object at 0x74bc8410>: Failed to establish a new connection: [Errno 111] Connection refused'))
mai 14 00:03:02 raspberrypi mainApp.py[2526]: [DataToLocalInfluxDB] : data not saved, timeout ! HTTPConnectionPool(host='localhost', port=8086): Max retries exceeded with url: /write?db=SensorData (Caused by NewConnectionError('<urllib3.connection.HTTPConnection object at 0x74bc8410>: Failed to establish a new connection: [Errno 111] Connection refused'))
mai 14 00:03:02 raspberrypi mainApp.py[2526]: [DataToLocalInfluxDB] : data not saved, timeout ! HTTPConnectionPool(host='localhost', port=8086): Max retries exceeded with url: /write?db=SensorData (Caused by NewConnectionError('<urllib3.connection.HTTPConnection object at 0x74bc8150>: Failed to establish a new connection: [Errno 111] Connection refused'))
mai 14 00:03:02 raspberrypi mainApp.py[2526]: [DataToLocalInfluxDB] : data not saved, timeout ! HTTPConnectionPool(host='localhost', port=8086): Max retries exceeded with url: /write?db=SensorData (Caused by NewConnectionError('<urllib3.connection.HTTPConnection object at 0x74b77d50>: Failed to establish a new connection: [Errno 111] Connection refused'))
mai 14 00:03:02 raspberrypi mainApp.py[2526]: [DataToLocalInfluxDB] : data not saved, timeout ! HTTPConnectionPool(host='localhost', port=8086): Max retries exceeded with url: /write?db=SensorData (Caused by NewConnectionError('<urllib3.connection.HTTPConnection object at 0x74b77730>: Failed to establish a new connection: [Errno 111] Connection refused'))
mai 14 00:03:02 raspberrypi mainApp.py[2526]: [DataToLocalInfluxDB] : data not saved, timeout ! HTTPConnectionPool(host='localhost', port=8086): Max retries exceeded with url: /write?db=SensorData (Caused by NewConnectionError('<urllib3.connection.HTTPConnection object at 0x74b77bf0>: Failed to establish a new connection: [Errno 111] Connection refused'))
mai 14 00:03:02 raspberrypi mainApp.py[2526]: [DataToLocalInfluxDB] : data not saved, timeout ! HTTPConnectionPool(host='localhost', port=8086): Max retries exceeded with url: /write?db=SensorData (Caused by NewConnectionError('<urllib3.connection.HTTPConnection object at 0x74be54d0>: Failed to establish a new connection: [Errno 111] Connection refused'))
mai 14 00:03:02 raspberrypi mainApp.py[2526]: [DataToLocalInfluxDB] : data not saved, timeout ! HTTPConnectionPool(host='localhost', port=8086): Max retries exceeded with url: /write?db=SensorData (Caused by NewConnectionError('<urllib3.connection.HTTPConnection object at 0x74b77330>: Failed to establish a new connection: [Errno 111] Connection refused'))
mai 14 00:03:02 raspberrypi mainApp.py[2526]: [DataToLocalInfluxDB] : data not saved, timeout ! HTTPConnectionPool(host='localhost', port=8086): Max retries exceeded with url: /write?db=SensorData (Caused by NewConnectionError('<urllib3.connection.HTTPConnection object at 0x74b77890>: Failed to establish a new connection: [Errno 111] Connection refused'))
mai 14 00:03:02 raspberrypi mainApp.py[2526]: [DataToLocalInfluxDB] : data not saved, timeout ! HTTPConnectionPool(host='localhost', port=8086): Max retries exceeded with url: /write?db=SensorData (Caused by NewConnectionError('<urllib3.connection.HTTPConnection object at 0x74bc8990>: Failed to establish a new connection: [Errno 111] Connection refused'))
mai 14 00:03:02 raspberrypi mainApp.py[2526]: [DataToLocalInfluxDB] : data not saved, timeout ! HTTPConnectionPool(host='localhost', port=8086): Max retries exceeded with url: /write?db=SensorData (Caused by NewConnectionError('<urllib3.connection.HTTPConnection object at 0x74bc8a90>: Failed to establish a new connection: [Errno 111] Connection refused'))
mai 14 00:03:02 raspberrypi mainApp.py[2526]: [DataToLocalInfluxDB] : data not saved, timeout ! HTTPConnectionPool(host='localhost', port=8086): Max retries exceeded with url: /write?db=SensorData (Caused by NewConnectionError('<urllib3.connection.HTTPConnection object at 0x74bc83f0>: Failed to establish a new connection: [Errno 111] Connection refused'))
mai 14 00:03:02 raspberrypi mainApp.py[2526]: [DataToLocalInfluxDB] : data not saved, timeout ! HTTPConnectionPool(host='localhost', port=8086): Max retries exceeded with url: /write?db=SensorData (Caused by NewConnectionError('<urllib3.connection.HTTPConnection object at 0x74bc8710>: Failed to establish a new connection: [Errno 111] Connection refused'))
mai 14 00:03:02 raspberrypi mainApp.py[2526]: [DataToLocalInfluxDB] : data not saved, timeout ! HTTPConnectionPool(host='localhost', port=8086): Max retries exceeded with url: /write?db=SensorData (Caused by NewConnectionError('<urllib3.connection.HTTPConnection object at 0x74bc8590>: Failed to establish a new connection: [Errno 111] Connection refused'))
mai 14 00:03:02 raspberrypi mainApp.py[2526]: [DataToLocalInfluxDB] : data not saved, timeout ! HTTPConnectionPool(host='localhost', port=8086): Max retries exceeded with url: /write?db=SensorData (Caused by NewConnectionError('<urllib3.connection.HTTPConnection object at 0x74b772f0>: Failed to establish a new connection: [Errno 111] Connection refused'))
mai 14 00:03:02 raspberrypi mainApp.py[2526]: [DataToLocalInfluxDB] : data not saved, timeout ! HTTPConnectionPool(host='localhost', port=8086): Max retries exceeded with url: /write?db=SensorData (Caused by NewConnectionError('<urllib3.connection.HTTPConnection object at 0x74b77ff0>: Failed to establish a new connection: [Errno 111] Connection refused'))
mai 14 00:03:03 raspberrypi mainApp.py[2526]: [DataToLocalInfluxDB] : data not saved, timeout ! HTTPConnectionPool(host='localhost', port=8086): Max retries exceeded with url: /write?db=SensorData (Caused by NewConnectionError('<urllib3.connection.HTTPConnection object at 0x74b772d0>: Failed to establish a new connection: [Errno 111] Connection refused'))
mai 14 00:03:03 raspberrypi mainApp.py[2526]: [DataToLocalInfluxDB] : data not saved, timeout ! HTTPConnectionPool(host='localhost', port=8086): Max retries exceeded with url: /write?db=SensorData (Caused by NewConnectionError('<urllib3.connection.HTTPConnection object at 0x74be5fd0>: Failed to establish a new connection: [Errno 111] Connection refused'))
mai 14 00:03:03 raspberrypi mainApp.py[2526]: [DataToLocalInfluxDB] : data not saved, timeout ! HTTPConnectionPool(host='localhost', port=8086): Max retries exceeded with url: /write?db=SensorData (Caused by NewConnectionError('<urllib3.connection.HTTPConnection object at 0x74bc8590>: Failed to establish a new connection: [Errno 111] Connection refused'))
mai 14 00:03:03 raspberrypi mainApp.py[2526]: [DataToLocalInfluxDB] : data not saved, timeout ! HTTPConnectionPool(host='localhost', port=8086): Max retries exceeded with url: /write?db=SensorData (Caused by NewConnectionError('<urllib3.connection.HTTPConnection object at 0x74bc8510>: Failed to establish a new connection: [Errno 111] Connection refused'))
mai 14 00:03:03 raspberrypi mainApp.py[2526]: [DataToLocalInfluxDB] : data not saved, timeout ! HTTPConnectionPool(host='localhost', port=8086): Max retries exceeded with url: /write?db=SensorData (Caused by NewConnectionError('<urllib3.connection.HTTPConnection object at 0x74b77110>: Failed to establish a new connection: [Errno 111] Connection refused'))
mai 14 00:03:03 raspberrypi mainApp.py[2526]: [DataToLocalInfluxDB] : data not saved, timeout ! HTTPConnectionPool(host='localhost', port=8086): Max retries exceeded with url: /write?db=SensorData (Caused by NewConnectionError('<urllib3.connection.HTTPConnection object at 0x74b77770>: Failed to establish a new connection: [Errno 111] Connection refused'))
mai 14 00:03:03 raspberrypi mainApp.py[2526]: [DataToLocalInfluxDB] : data not saved, timeout ! HTTPConnectionPool(host='localhost', port=8086): Max retries exceeded with url: /write?db=SensorData (Caused by NewConnectionError('<urllib3.connection.HTTPConnection object at 0x74b77eb0>: Failed to establish a new connection: [Errno 111] Connection refused'))
mai 14 00:03:03 raspberrypi mainApp.py[2526]: [DataToLocalInfluxDB] : data not saved, timeout ! HTTPConnectionPool(host='localhost', port=8086): Max retries exceeded with url: /write?db=SensorData (Caused by NewConnectionError('<urllib3.connection.HTTPConnection object at 0x74b77330>: Failed to establish a new connection: [Errno 111] Connection refused'))
mai 14 00:03:03 raspberrypi mainApp.py[2526]: [DataToLocalInfluxDB] : data not saved, timeout ! HTTPConnectionPool(host='localhost', port=8086): Max retries exceeded with url: /write?db=SensorData (Caused by NewConnectionError('<urllib3.connection.HTTPConnection object at 0x74b77070>: Failed to establish a new connection: [Errno 111] Connection refused'))
mai 14 00:03:03 raspberrypi mainApp.py[2526]: [DataToLocalInfluxDB] : data not saved, timeout ! HTTPConnectionPool(host='localhost', port=8086): Max retries exceeded with url: /write?db=SensorData (Caused by NewConnectionError('<urllib3.connection.HTTPConnection object at 0x74bc8c70>: Failed to establish a new connection: [Errno 111] Connection refused'))
mai 14 00:03:03 raspberrypi mainApp.py[2526]: [DataToLocalInfluxDB] : data not saved, timeout ! HTTPConnectionPool(host='localhost', port=8086): Max retries exceeded with url: /write?db=SensorData (Caused by NewConnectionError('<urllib3.connection.HTTPConnection object at 0x74bc8330>: Failed to establish a new connection: [Errno 111] Connection refused'))
mai 14 00:03:03 raspberrypi mainApp.py[2526]: [DataToLocalInfluxDB] : data not saved, timeout ! HTTPConnectionPool(host='localhost', port=8086): Max retries exceeded with url: /write?db=SensorData (Caused by NewConnectionError('<urllib3.connection.HTTPConnection object at 0x74bc8d90>: Failed to establish a new connection: [Errno 111] Connection refused'))
mai 14 00:03:03 raspberrypi mainApp.py[2526]: [DataToLocalInfluxDB] : data not saved, timeout ! HTTPConnectionPool(host='localhost', port=8086): Max retries exceeded with url: /write?db=SensorData (Caused by NewConnectionError('<urllib3.connection.HTTPConnection object at 0x74be5f50>: Failed to establish a new connection: [Errno 111] Connection refused'))
mai 14 00:03:03 raspberrypi mainApp.py[2526]: [DataToLocalInfluxDB] : data not saved, timeout ! HTTPConnectionPool(host='localhost', port=8086): Max retries exceeded with url: /write?db=SensorData (Caused by NewConnectionError('<urllib3.connection.HTTPConnection object at 0x74bc8990>: Failed to establish a new connection: [Errno 111] Connection refused'))
mai 14 00:03:03 raspberrypi mainApp.py[2526]: [DataToLocalInfluxDB] : data not saved, timeout ! HTTPConnectionPool(host='localhost', port=8086): Max retries exceeded with url: /write?db=SensorData (Caused by NewConnectionError('<urllib3.connection.HTTPConnection object at 0x74bc8eb0>: Failed to establish a new connection: [Errno 111] Connection refused'))
mai 14 00:03:03 raspberrypi mainApp.py[2526]: [DataToLocalInfluxDB] : data not saved, timeout ! HTTPConnectionPool(host='localhost', port=8086): Max retries exceeded with url: /write?db=SensorData (Caused by NewConnectionError('<urllib3.connection.HTTPConnection object at 0x74b77110>: Failed to establish a new connection: [Errno 111] Connection refused'))
mai 14 00:03:04 raspberrypi mainApp.py[2526]: [DataToLocalInfluxDB] : data not saved, timeout ! HTTPConnectionPool(host='localhost', port=8086): Max retries exceeded with url: /write?db=SensorData (Caused by NewConnectionError('<urllib3.connection.HTTPConnection object at 0x74b77810>: Failed to establish a new connection: [Errno 111] Connection refused'))
mai 14 00:03:04 raspberrypi mainApp.py[2526]: [DataToLocalInfluxDB] : data not saved, timeout ! HTTPConnectionPool(host='localhost', port=8086): Max retries exceeded with url: /write?db=SensorData (Caused by NewConnectionError('<urllib3.connection.HTTPConnection object at 0x74b77710>: Failed to establish a new connection: [Errno 111] Connection refused'))
mai 14 00:03:04 raspberrypi mainApp.py[2526]: [DataToLocalInfluxDB] : data not saved, timeout ! HTTPConnectionPool(host='localhost', port=8086): Max retries exceeded with url: /write?db=SensorData (Caused by NewConnectionError('<urllib3.connection.HTTPConnection object at 0x74b77cd0>: Failed to establish a new connection: [Errno 111] Connection refused'))
mai 14 00:03:04 raspberrypi mainApp.py[2526]: [DataToLocalInfluxDB] : data not saved, timeout ! HTTPConnectionPool(host='localhost', port=8086): Max retries exceeded with url: /write?db=SensorData (Caused by NewConnectionError('<urllib3.connection.HTTPConnection object at 0x74b77d50>: Failed to establish a new connection: [Errno 111] Connection refused'))
mai 14 00:03:04 raspberrypi mainApp.py[2526]: [DataToLocalInfluxDB] : data not saved, timeout ! HTTPConnectionPool(host='localhost', port=8086): Max retries exceeded with url: /write?db=SensorData (Caused by NewConnectionError('<urllib3.connection.HTTPConnection object at 0x74b77c70>: Failed to establish a new connection: [Errno 111] Connection refused'))
mai 14 00:03:04 raspberrypi mainApp.py[2526]: [DataToLocalInfluxDB] : data not saved, timeout ! HTTPConnectionPool(host='localhost', port=8086): Max retries exceeded with url: /write?db=SensorData (Caused by NewConnectionError('<urllib3.connection.HTTPConnection object at 0x74bc8b90>: Failed to establish a new connection: [Errno 111] Connection refused'))
mai 14 00:03:04 raspberrypi mainApp.py[2526]: [DataToLocalInfluxDB] : data not saved, timeout ! HTTPConnectionPool(host='localhost', port=8086): Max retries exceeded with url: /write?db=SensorData (Caused by NewConnectionError('<urllib3.connection.HTTPConnection object at 0x74bc8770>: Failed to establish a new connection: [Errno 111] Connection refused'))
mai 14 00:03:04 raspberrypi mainApp.py[2526]: [DataToLocalInfluxDB] : data not saved, timeout ! HTTPConnectionPool(host='localhost', port=8086): Max retries exceeded with url: /write?db=SensorData (Caused by NewConnectionError('<urllib3.connection.HTTPConnection object at 0x74be5390>: Failed to establish a new connection: [Errno 111] Connection refused'))
mai 14 00:03:04 raspberrypi mainApp.py[2526]: [DataToLocalInfluxDB] : data not saved, timeout ! HTTPConnectionPool(host='localhost', port=8086): Max retries exceeded with url: /write?db=SensorData (Caused by NewConnectionError('<urllib3.connection.HTTPConnection object at 0x74bc8ef0>: Failed to establish a new connection: [Errno 111] Connection refused'))
mai 14 00:03:04 raspberrypi mainApp.py[2526]: [DataToLocalInfluxDB] : data not saved, timeout ! HTTPConnectionPool(host='localhost', port=8086): Max retries exceeded with url: /write?db=SensorData (Caused by NewConnectionError('<urllib3.connection.HTTPConnection object at 0x74bc8330>: Failed to establish a new connection: [Errno 111] Connection refused'))
mai 14 00:03:04 raspberrypi mainApp.py[2526]: [DataToLocalInfluxDB] : data not saved, timeout ! HTTPConnectionPool(host='localhost', port=8086): Max retries exceeded with url: /write?db=SensorData (Caused by NewConnectionError('<urllib3.connection.HTTPConnection object at 0x74b77e30>: Failed to establish a new connection: [Errno 111] Connection refused'))
mai 14 00:03:04 raspberrypi mainApp.py[2526]: [DataToLocalInfluxDB] : data not saved, timeout ! HTTPConnectionPool(host='localhost', port=8086): Max retries exceeded with url: /write?db=SensorData (Caused by NewConnectionError('<urllib3.connection.HTTPConnection object at 0x74b77cf0>: Failed to establish a new connection: [Errno 111] Connection refused'))
mai 14 00:03:04 raspberrypi mainApp.py[2526]: [DataToLocalInfluxDB] : data not saved, timeout ! HTTPConnectionPool(host='localhost', port=8086): Max retries exceeded with url: /write?db=SensorData (Caused by NewConnectionError('<urllib3.connection.HTTPConnection object at 0x74b778d0>: Failed to establish a new connection: [Errno 111] Connection refused'))
mai 14 00:03:04 raspberrypi mainApp.py[2526]: [DataToLocalInfluxDB] : data not saved, timeout ! HTTPConnectionPool(host='localhost', port=8086): Max retries exceeded with url: /write?db=SensorData (Caused by NewConnectionError('<urllib3.connection.HTTPConnection object at 0x74b775b0>: Failed to establish a new connection: [Errno 111] Connection refused'))
mai 14 00:03:04 raspberrypi mainApp.py[2526]: [DataToLocalInfluxDB] : data not saved, timeout ! HTTPConnectionPool(host='localhost', port=8086): Max retries exceeded with url: /write?db=SensorData (Caused by NewConnectionError('<urllib3.connection.HTTPConnection object at 0x74b77db0>: Failed to establish a new connection: [Errno 111] Connection refused'))
mai 14 00:03:04 raspberrypi mainApp.py[2526]: [DataToLocalInfluxDB] : data not saved, timeout ! HTTPConnectionPool(host='localhost', port=8086): Max retries exceeded with url: /write?db=SensorData (Caused by NewConnectionError('<urllib3.connection.HTTPConnection object at 0x74b77830>: Failed to establish a new connection: [Errno 111] Connection refused'))
mai 14 00:03:04 raspberrypi mainApp.py[2526]: [DataToLocalInfluxDB] : data not saved, timeout ! HTTPConnectionPool(host='localhost', port=8086): Max retries exceeded with url: /write?db=SensorData (Caused by NewConnectionError('<urllib3.connection.HTTPConnection object at 0x74bc8e10>: Failed to establish a new connection: [Errno 111] Connection refused'))
mai 14 00:03:05 raspberrypi mainApp.py[2526]: [DataToLocalInfluxDB] : data not saved, timeout ! HTTPConnectionPool(host='localhost', port=8086): Max retries exceeded with url: /write?db=SensorData (Caused by NewConnectionError('<urllib3.connection.HTTPConnection object at 0x74bc8e90>: Failed to establish a new connection: [Errno 111] Connection refused'))
mai 14 00:03:05 raspberrypi mainApp.py[2526]: [DataToLocalInfluxDB] : data not saved, timeout ! HTTPConnectionPool(host='localhost', port=8086): Max retries exceeded with url: /write?db=SensorData (Caused by NewConnectionError('<urllib3.connection.HTTPConnection object at 0x74be57f0>: Failed to establish a new connection: [Errno 111] Connection refused'))
mai 14 00:03:05 raspberrypi mainApp.py[2526]: [DataToLocalInfluxDB] : data not saved, timeout ! HTTPConnectionPool(host='localhost', port=8086): Max retries exceeded with url: /write?db=SensorData (Caused by NewConnectionError('<urllib3.connection.HTTPConnection object at 0x74bc8870>: Failed to establish a new connection: [Errno 111] Connection refused'))
mai 14 00:03:05 raspberrypi mainApp.py[2526]: [DataToLocalInfluxDB] : data not saved, timeout ! HTTPConnectionPool(host='localhost', port=8086): Max retries exceeded with url: /write?db=SensorData (Caused by NewConnectionError('<urllib3.connection.HTTPConnection object at 0x74bc8610>: Failed to establish a new connection: [Errno 111] Connection refused'))
mai 14 00:03:05 raspberrypi mainApp.py[2526]: [DataToLocalInfluxDB] : data not saved, timeout ! HTTPConnectionPool(host='localhost', port=8086): Max retries exceeded with url: /write?db=SensorData (Caused by NewConnectionError('<urllib3.connection.HTTPConnection object at 0x74bc8230>: Failed to establish a new connection: [Errno 111] Connection refused'))
mai 14 00:03:05 raspberrypi mainApp.py[2526]: [DataToLocalInfluxDB] : data not saved, timeout ! HTTPConnectionPool(host='localhost', port=8086): Max retries exceeded with url: /write?db=SensorData (Caused by NewConnectionError('<urllib3.connection.HTTPConnection object at 0x74b77970>: Failed to establish a new connection: [Errno 111] Connection refused'))
mai 14 00:03:05 raspberrypi mainApp.py[2526]: [DataToLocalInfluxDB] : data not saved, timeout ! HTTPConnectionPool(host='localhost', port=8086): Max retries exceeded with url: /write?db=SensorData (Caused by NewConnectionError('<urllib3.connection.HTTPConnection object at 0x74b77f30>: Failed to establish a new connection: [Errno 111] Connection refused'))
mai 14 00:03:05 raspberrypi mainApp.py[2526]: [DataToLocalInfluxDB] : data not saved, timeout ! HTTPConnectionPool(host='localhost', port=8086): Max retries exceeded with url: /write?db=SensorData (Caused by NewConnectionError('<urllib3.connection.HTTPConnection object at 0x74b77a10>: Failed to establish a new connection: [Errno 111] Connection refused'))
mai 14 00:03:05 raspberrypi mainApp.py[2526]: [DataToLocalInfluxDB] : data not saved, timeout ! HTTPConnectionPool(host='localhost', port=8086): Max retries exceeded with url: /write?db=SensorData (Caused by NewConnectionError('<urllib3.connection.HTTPConnection object at 0x74b77690>: Failed to establish a new connection: [Errno 111] Connection refused'))
mai 14 00:03:05 raspberrypi mainApp.py[2526]: [DataToLocalInfluxDB] : data not saved, timeout ! HTTPConnectionPool(host='localhost', port=8086): Max retries exceeded with url: /write?db=SensorData (Caused by NewConnectionError('<urllib3.connection.HTTPConnection object at 0x74b77070>: Failed to establish a new connection: [Errno 111] Connection refused'))
mai 14 00:03:05 raspberrypi mainApp.py[2526]: [DataToLocalInfluxDB] : data not saved, timeout ! HTTPConnectionPool(host='localhost', port=8086): Max retries exceeded with url: /write?db=SensorData (Caused by NewConnectionError('<urllib3.connection.HTTPConnection object at 0x74bc8db0>: Failed to establish a new connection: [Errno 111] Connection refused'))
mai 14 00:03:05 raspberrypi mainApp.py[2526]: [DataToLocalInfluxDB] : data not saved, timeout ! HTTPConnectionPool(host='localhost', port=8086): Max retries exceeded with url: /write?db=SensorData (Caused by NewConnectionError('<urllib3.connection.HTTPConnection object at 0x74bc8e30>: Failed to establish a new connection: [Errno 111] Connection refused'))
mai 14 00:03:05 raspberrypi mainApp.py[2526]: [DataToLocalInfluxDB] : data not saved, timeout ! HTTPConnectionPool(host='localhost', port=8086): Max retries exceeded with url: /write?db=SensorData (Caused by NewConnectionError('<urllib3.connection.HTTPConnection object at 0x74be5230>: Failed to establish a new connection: [Errno 111] Connection refused'))
mai 14 00:03:05 raspberrypi mainApp.py[2526]: [DataToLocalInfluxDB] : data not saved, timeout ! HTTPConnectionPool(host='localhost', port=8086): Max retries exceeded with url: /write?db=SensorData (Caused by NewConnectionError('<urllib3.connection.HTTPConnection object at 0x74bc8d50>: Failed to establish a new connection: [Errno 111] Connection refused'))
mai 14 00:03:05 raspberrypi mainApp.py[2526]: [DataToLocalInfluxDB] : data not saved, timeout ! HTTPConnectionPool(host='localhost', port=8086): Max retries exceeded with url: /write?db=SensorData (Caused by NewConnectionError('<urllib3.connection.HTTPConnection object at 0x74bc8dd0>: Failed to establish a new connection: [Errno 111] Connection refused'))
mai 14 00:03:05 raspberrypi mainApp.py[2526]: [DataToLocalInfluxDB] : data not saved, timeout ! HTTPConnectionPool(host='localhost', port=8086): Max retries exceeded with url: /write?db=SensorData (Caused by NewConnectionError('<urllib3.connection.HTTPConnection object at 0x74bc88d0>: Failed to establish a new connection: [Errno 111] Connection refused'))
mai 14 00:03:05 raspberrypi mainApp.py[2526]: [DataToLocalInfluxDB] : data not saved, timeout ! HTTPConnectionPool(host='localhost', port=8086): Max retries exceeded with url: /write?db=SensorData (Caused by NewConnectionError('<urllib3.connection.HTTPConnection object at 0x74b77c70>: Failed to establish a new connection: [Errno 111] Connection refused'))
mai 14 00:03:05 raspberrypi mainApp.py[2526]: [DataToLocalInfluxDB] : data not saved, timeout ! HTTPConnectionPool(host='localhost', port=8086): Max retries exceeded with url: /write?db=SensorData (Caused by NewConnectionError('<urllib3.connection.HTTPConnection object at 0x74b77730>: Failed to establish a new connection: [Errno 111] Connection refused'))
mai 14 00:03:05 raspberrypi mainApp.py[2526]: [DataToLocalInfluxDB] : data not saved, timeout ! HTTPConnectionPool(host='localhost', port=8086): Max retries exceeded with url: /write?db=SensorData (Caused by NewConnectionError('<urllib3.connection.HTTPConnection object at 0x74be54f0>: Failed to establish a new connection: [Errno 111] Connection refused'))
mai 14 00:03:06 raspberrypi mainApp.py[2526]: [DataToLocalInfluxDB] : data not saved, timeout ! HTTPConnectionPool(host='localhost', port=8086): Max retries exceeded with url: /write?db=SensorData (Caused by NewConnectionError('<urllib3.connection.HTTPConnection object at 0x74b77670>: Failed to establish a new connection: [Errno 111] Connection refused'))
mai 14 00:03:06 raspberrypi mainApp.py[2526]: [DataToLocalInfluxDB] : data not saved, timeout ! HTTPConnectionPool(host='localhost', port=8086): Max retries exceeded with url: /write?db=SensorData (Caused by NewConnectionError('<urllib3.connection.HTTPConnection object at 0x74b77ab0>: Failed to establish a new connection: [Errno 111] Connection refused'))
mai 14 00:03:06 raspberrypi mainApp.py[2526]: [DataToLocalInfluxDB] : data not saved, timeout ! HTTPConnectionPool(host='localhost', port=8086): Max retries exceeded with url: /write?db=SensorData (Caused by NewConnectionError('<urllib3.connection.HTTPConnection object at 0x74bc87b0>: Failed to establish a new connection: [Errno 111] Connection refused'))
mai 14 00:03:06 raspberrypi mainApp.py[2526]: [DataToLocalInfluxDB] : data not saved, timeout ! HTTPConnectionPool(host='localhost', port=8086): Max retries exceeded with url: /write?db=SensorData (Caused by NewConnectionError('<urllib3.connection.HTTPConnection object at 0x74bc88f0>: Failed to establish a new connection: [Errno 111] Connection refused'))
mai 14 00:03:06 raspberrypi mainApp.py[2526]: [DataToLocalInfluxDB] : data not saved, timeout ! HTTPConnectionPool(host='localhost', port=8086): Max retries exceeded with url: /write?db=SensorData (Caused by NewConnectionError('<urllib3.connection.HTTPConnection object at 0x74bc8b30>: Failed to establish a new connection: [Errno 111] Connection refused'))
mai 14 00:03:06 raspberrypi mainApp.py[2526]: [DataToLocalInfluxDB] : data not saved, timeout ! HTTPConnectionPool(host='localhost', port=8086): Max retries exceeded with url: /write?db=SensorData (Caused by NewConnectionError('<urllib3.connection.HTTPConnection object at 0x74bc8450>: Failed to establish a new connection: [Errno 111] Connection refused'))
mai 14 00:03:06 raspberrypi mainApp.py[2526]: [DataToLocalInfluxDB] : data not saved, timeout ! HTTPConnectionPool(host='localhost', port=8086): Max retries exceeded with url: /write?db=SensorData (Caused by NewConnectionError('<urllib3.connection.HTTPConnection object at 0x74bc8870>: Failed to establish a new connection: [Errno 111] Connection refused'))
mai 14 00:03:06 raspberrypi mainApp.py[2526]: [DataToLocalInfluxDB] : data not saved, timeout ! HTTPConnectionPool(host='localhost', port=8086): Max retries exceeded with url: /write?db=SensorData (Caused by NewConnectionError('<urllib3.connection.HTTPConnection object at 0x74bc81d0>: Failed to establish a new connection: [Errno 111] Connection refused'))
mai 14 00:03:06 raspberrypi mainApp.py[2526]: [DataToLocalInfluxDB] : data not saved, timeout ! HTTPConnectionPool(host='localhost', port=8086): Max retries exceeded with url: /write?db=SensorData (Caused by NewConnectionError('<urllib3.connection.HTTPConnection object at 0x74b77c90>: Failed to establish a new connection: [Errno 111] Connection refused'))
mai 14 00:03:06 raspberrypi mainApp.py[2526]: [DataToLocalInfluxDB] : data not saved, timeout ! HTTPConnectionPool(host='localhost', port=8086): Max retries exceeded with url: /write?db=SensorData (Caused by NewConnectionError('<urllib3.connection.HTTPConnection object at 0x74b777b0>: Failed to establish a new connection: [Errno 111] Connection refused'))
mai 14 00:03:06 raspberrypi mainApp.py[2526]: [DataToLocalInfluxDB] : data not saved, timeout ! HTTPConnectionPool(host='localhost', port=8086): Max retries exceeded with url: /write?db=SensorData (Caused by NewConnectionError('<urllib3.connection.HTTPConnection object at 0x74be5f50>: Failed to establish a new connection: [Errno 111] Connection refused'))
mai 14 00:03:06 raspberrypi mainApp.py[2526]: [DataToLocalInfluxDB] : data not saved, timeout ! HTTPConnectionPool(host='localhost', port=8086): Max retries exceeded with url: /write?db=SensorData (Caused by NewConnectionError('<urllib3.connection.HTTPConnection object at 0x74b77890>: Failed to establish a new connection: [Errno 111] Connection refused'))
mai 14 00:03:06 raspberrypi mainApp.py[2526]: [DataToLocalInfluxDB] : data not saved, timeout ! HTTPConnectionPool(host='localhost', port=8086): Max retries exceeded with url: /write?db=SensorData (Caused by NewConnectionError('<urllib3.connection.HTTPConnection object at 0x74b77c70>: Failed to establish a new connection: [Errno 111] Connection refused'))
mai 14 00:03:06 raspberrypi mainApp.py[2526]: [DataToLocalInfluxDB] : data not saved, timeout ! HTTPConnectionPool(host='localhost', port=8086): Max retries exceeded with url: /write?db=SensorData (Caused by NewConnectionError('<urllib3.connection.HTTPConnection object at 0x74bc86d0>: Failed to establish a new connection: [Errno 111] Connection refused'))
mai 14 00:03:06 raspberrypi mainApp.py[2526]: [DataToLocalInfluxDB] : data not saved, timeout ! HTTPConnectionPool(host='localhost', port=8086): Max retries exceeded with url: /write?db=SensorData (Caused by NewConnectionError('<urllib3.connection.HTTPConnection object at 0x74bc8a70>: Failed to establish a new connection: [Errno 111] Connection refused'))
mai 14 00:03:06 raspberrypi mainApp.py[2526]: [DataToLocalInfluxDB] : data not saved, timeout ! HTTPConnectionPool(host='localhost', port=8086): Max retries exceeded with url: /write?db=SensorData (Caused by NewConnectionError('<urllib3.connection.HTTPConnection object at 0x74bc8230>: Failed to establish a new connection: [Errno 111] Connection refused'))
mai 14 00:03:06 raspberrypi mainApp.py[2526]: [DataToLocalInfluxDB] : data not saved, timeout ! HTTPConnectionPool(host='localhost', port=8086): Max retries exceeded with url: /write?db=SensorData (Caused by NewConnectionError('<urllib3.connection.HTTPConnection object at 0x74bc8b30>: Failed to establish a new connection: [Errno 111] Connection refused'))
mai 14 00:03:06 raspberrypi mainApp.py[2526]: [DataToLocalInfluxDB] : data not saved, timeout ! HTTPConnectionPool(host='localhost', port=8086): Max retries exceeded with url: /write?db=SensorData (Caused by NewConnectionError('<urllib3.connection.HTTPConnection object at 0x74bc8770>: Failed to establish a new connection: [Errno 111] Connection refused'))
mai 14 00:03:07 raspberrypi mainApp.py[2526]: [DataToLocalInfluxDB] : data not saved, timeout ! HTTPConnectionPool(host='localhost', port=8086): Max retries exceeded with url: /write?db=SensorData (Caused by NewConnectionError('<urllib3.connection.HTTPConnection object at 0x74bc8890>: Failed to establish a new connection: [Errno 111] Connection refused'))
mai 14 00:03:07 raspberrypi mainApp.py[2526]: [DataToLocalInfluxDB] : data not saved, timeout ! HTTPConnectionPool(host='localhost', port=8086): Max retries exceeded with url: /write?db=SensorData (Caused by NewConnectionError('<urllib3.connection.HTTPConnection object at 0x74b777d0>: Failed to establish a new connection: [Errno 111] Connection refused'))
mai 14 00:03:07 raspberrypi mainApp.py[2526]: [DataToLocalInfluxDB] : data not saved, timeout ! HTTPConnectionPool(host='localhost', port=8086): Max retries exceeded with url: /write?db=SensorData (Caused by NewConnectionError('<urllib3.connection.HTTPConnection object at 0x74b77690>: Failed to establish a new connection: [Errno 111] Connection refused'))
mai 14 00:03:07 raspberrypi mainApp.py[2526]: [DataToLocalInfluxDB] : write_points 545
mai 14 00:03:07 raspberrypi mainApp.py[2526]: [DataToLocalInfluxDB] : write_points 100
mai 14 00:03:07 raspberrypi mainApp.py[2526]: [DataToLocalInfluxDB] : write_points 100
